[2025-10-15 21:48:15,208: INFO/MainProcess] Connected to redis://localhost:6379/0
[2025-10-15 21:48:15,211: INFO/MainProcess] mingle: searching for neighbors
[2025-10-15 21:48:16,216: INFO/MainProcess] mingle: all alone
[2025-10-15 21:48:16,247: INFO/MainProcess] celery@Xaviers-MacBook-Pro.local ready.
[2025-10-15 21:56:52,772: INFO/MainProcess] Connected to redis://localhost:6379/0
[2025-10-15 21:56:52,775: INFO/MainProcess] mingle: searching for neighbors
[2025-10-15 21:56:53,787: INFO/MainProcess] mingle: all alone
[2025-10-15 21:56:53,834: INFO/MainProcess] celery@Xaviers-MacBook-Pro.local ready.
[2025-10-15 22:00:00,047: ERROR/MainProcess] Received unregistered task of type 'backend.bot.tasks.collect_transactions'.
The message has been ignored and discarded.

Did you remember to import the module containing this task?
Or maybe you're using relative imports?

Please see
https://docs.celeryq.dev/en/latest/internals/protocol.html
for more information.

The full contents of the message body was:
b'[[], {}, {"callbacks": null, "errbacks": null, "chain": null, "chord": null}]' (77b)

The full contents of the message headers:
{'lang': 'py', 'task': 'backend.bot.tasks.collect_transactions', 'id': '57429389-e037-4961-9680-e5c59e9b2c66', 'shadow': None, 'eta': None, 'expires': '2025-10-15T22:25:00.028184-04:00', 'group': None, 'group_index': None, 'retries': 0, 'timelimit': [None, None], 'root_id': '57429389-e037-4961-9680-e5c59e9b2c66', 'parent_id': None, 'argsrepr': '()', 'kwargsrepr': '{}', 'origin': 'gen25372@Xaviers-MacBook-Pro.local', 'ignore_result': False, 'replaced_task_nesting': 0, 'stamped_headers': None, 'stamps': {}}

The delivery info for this task is:
{'exchange': '', 'routing_key': 'heartbeat_bot'}
Traceback (most recent call last):
  File "/Library/Frameworks/Python.framework/Versions/3.12/lib/python3.12/site-packages/celery/worker/consumer/consumer.py", line 662, in on_task_received
    strategy = strategies[type_]
               ~~~~~~~~~~^^^^^^^
KeyError: 'backend.bot.tasks.collect_transactions'
[2025-10-15 22:10:37,296: INFO/MainProcess] Connected to redis://localhost:6379/0
[2025-10-15 22:10:37,298: INFO/MainProcess] mingle: searching for neighbors
[2025-10-15 22:10:38,323: INFO/MainProcess] mingle: all alone
[2025-10-15 22:10:38,351: INFO/MainProcess] celery@Xaviers-MacBook-Pro.local ready.
[2025-10-15 22:30:00,082: ERROR/MainProcess] Received unregistered task of type 'backend.bot.tasks.collect_transactions'.
The message has been ignored and discarded.

Did you remember to import the module containing this task?
Or maybe you're using relative imports?

Please see
https://docs.celeryq.dev/en/latest/internals/protocol.html
for more information.

The full contents of the message body was:
b'[[], {}, {"callbacks": null, "errbacks": null, "chain": null, "chord": null}]' (77b)

The full contents of the message headers:
{'lang': 'py', 'task': 'backend.bot.tasks.collect_transactions', 'id': '978736ee-3557-49cb-8eea-4b131aa0c59c', 'shadow': None, 'eta': None, 'expires': '2025-10-15T22:55:00.056742-04:00', 'group': None, 'group_index': None, 'retries': 0, 'timelimit': [None, None], 'root_id': '978736ee-3557-49cb-8eea-4b131aa0c59c', 'parent_id': None, 'argsrepr': '()', 'kwargsrepr': '{}', 'origin': 'gen40017@Xaviers-MacBook-Pro.local', 'ignore_result': False, 'replaced_task_nesting': 0, 'stamped_headers': None, 'stamps': {}}

The delivery info for this task is:
{'exchange': '', 'routing_key': 'heartbeat_bot'}
Traceback (most recent call last):
  File "/Library/Frameworks/Python.framework/Versions/3.12/lib/python3.12/site-packages/celery/worker/consumer/consumer.py", line 662, in on_task_received
    strategy = strategies[type_]
               ~~~~~~~~~~^^^^^^^
KeyError: 'backend.bot.tasks.collect_transactions'
[2025-10-15 22:57:44,124: INFO/MainProcess] Connected to redis://localhost:6379/0
[2025-10-15 22:57:44,127: INFO/MainProcess] mingle: searching for neighbors
[2025-10-15 22:57:45,209: INFO/MainProcess] mingle: all alone
[2025-10-15 22:57:45,299: INFO/MainProcess] celery@Xaviers-MacBook-Pro.local ready.
[2025-10-15 23:00:00,046: ERROR/MainProcess] Received unregistered task of type 'backend.bot.tasks.collect_transactions'.
The message has been ignored and discarded.

Did you remember to import the module containing this task?
Or maybe you're using relative imports?

Please see
https://docs.celeryq.dev/en/latest/internals/protocol.html
for more information.

The full contents of the message body was:
b'[[], {}, {"callbacks": null, "errbacks": null, "chain": null, "chord": null}]' (77b)

The full contents of the message headers:
{'lang': 'py', 'task': 'backend.bot.tasks.collect_transactions', 'id': '130fb76d-d34f-42ff-9592-0948f706b2cd', 'shadow': None, 'eta': None, 'expires': '2025-10-15T23:25:00.031820-04:00', 'group': None, 'group_index': None, 'retries': 0, 'timelimit': [None, None], 'root_id': '130fb76d-d34f-42ff-9592-0948f706b2cd', 'parent_id': None, 'argsrepr': '()', 'kwargsrepr': '{}', 'origin': 'gen88489@Xaviers-MacBook-Pro.local', 'ignore_result': False, 'replaced_task_nesting': 0, 'stamped_headers': None, 'stamps': {}}

The delivery info for this task is:
{'exchange': '', 'routing_key': 'heartbeat_bot'}
Traceback (most recent call last):
  File "/Library/Frameworks/Python.framework/Versions/3.12/lib/python3.12/site-packages/celery/worker/consumer/consumer.py", line 662, in on_task_received
    strategy = strategies[type_]
               ~~~~~~~~~~^^^^^^^
KeyError: 'backend.bot.tasks.collect_transactions'
[2025-10-15 23:24:06,890: INFO/MainProcess] Connected to redis://localhost:6379/0
[2025-10-15 23:24:06,892: INFO/MainProcess] mingle: searching for neighbors
[2025-10-15 23:24:07,918: INFO/MainProcess] mingle: all alone
[2025-10-15 23:24:08,051: INFO/MainProcess] celery@Xaviers-MacBook-Pro.local ready.
[2025-10-15 23:30:00,030: ERROR/MainProcess] Received unregistered task of type 'backend.bot.tasks.collect_transactions'.
The message has been ignored and discarded.

Did you remember to import the module containing this task?
Or maybe you're using relative imports?

Please see
https://docs.celeryq.dev/en/latest/internals/protocol.html
for more information.

The full contents of the message body was:
b'[[], {}, {"callbacks": null, "errbacks": null, "chain": null, "chord": null}]' (77b)

The full contents of the message headers:
{'lang': 'py', 'task': 'backend.bot.tasks.collect_transactions', 'id': 'a528df3e-089a-43b0-a551-a0890d5a6041', 'shadow': None, 'eta': None, 'expires': '2025-10-15T23:55:00.018054-04:00', 'group': None, 'group_index': None, 'retries': 0, 'timelimit': [None, None], 'root_id': 'a528df3e-089a-43b0-a551-a0890d5a6041', 'parent_id': None, 'argsrepr': '()', 'kwargsrepr': '{}', 'origin': 'gen17308@Xaviers-MacBook-Pro.local', 'ignore_result': False, 'replaced_task_nesting': 0, 'stamped_headers': None, 'stamps': {}}

The delivery info for this task is:
{'exchange': '', 'routing_key': 'heartbeat_bot'}
Traceback (most recent call last):
  File "/Library/Frameworks/Python.framework/Versions/3.12/lib/python3.12/site-packages/celery/worker/consumer/consumer.py", line 662, in on_task_received
    strategy = strategies[type_]
               ~~~~~~~~~~^^^^^^^
KeyError: 'backend.bot.tasks.collect_transactions'
[2025-10-16 07:27:20,105: ERROR/MainProcess] Received unregistered task of type 'backend.bot.tasks.aggregate_and_synthesize_news'.
The message has been ignored and discarded.

Did you remember to import the module containing this task?
Or maybe you're using relative imports?

Please see
https://docs.celeryq.dev/en/latest/internals/protocol.html
for more information.

The full contents of the message body was:
b'[[], {}, {"callbacks": null, "errbacks": null, "chain": null, "chord": null}]' (77b)

The full contents of the message headers:
{'lang': 'py', 'task': 'backend.bot.tasks.aggregate_and_synthesize_news', 'id': 'e1740361-0d25-46c1-a8b6-1562078505c4', 'shadow': None, 'eta': None, 'expires': '2025-10-16T12:27:20.102088-04:00', 'group': None, 'group_index': None, 'retries': 0, 'timelimit': [None, None], 'root_id': 'e1740361-0d25-46c1-a8b6-1562078505c4', 'parent_id': None, 'argsrepr': '()', 'kwargsrepr': '{}', 'origin': 'gen17308@Xaviers-MacBook-Pro.local', 'ignore_result': False, 'replaced_task_nesting': 0, 'stamped_headers': None, 'stamps': {}}

The delivery info for this task is:
{'exchange': '', 'routing_key': 'heartbeat_bot'}
Traceback (most recent call last):
  File "/Library/Frameworks/Python.framework/Versions/3.12/lib/python3.12/site-packages/celery/worker/consumer/consumer.py", line 662, in on_task_received
    strategy = strategies[type_]
               ~~~~~~~~~~^^^^^^^
KeyError: 'backend.bot.tasks.aggregate_and_synthesize_news'
[2025-10-16 07:27:20,109: ERROR/MainProcess] Received unregistered task of type 'backend.bot.tasks.collect_transactions'.
The message has been ignored and discarded.

Did you remember to import the module containing this task?
Or maybe you're using relative imports?

Please see
https://docs.celeryq.dev/en/latest/internals/protocol.html
for more information.

The full contents of the message body was:
b'[[], {}, {"callbacks": null, "errbacks": null, "chain": null, "chord": null}]' (77b)

The full contents of the message headers:
{'lang': 'py', 'task': 'backend.bot.tasks.collect_transactions', 'id': 'e5bedbf2-37c6-427a-9a70-0c55d8e65e99', 'shadow': None, 'eta': None, 'expires': '2025-10-16T07:52:20.105544-04:00', 'group': None, 'group_index': None, 'retries': 0, 'timelimit': [None, None], 'root_id': 'e5bedbf2-37c6-427a-9a70-0c55d8e65e99', 'parent_id': None, 'argsrepr': '()', 'kwargsrepr': '{}', 'origin': 'gen17308@Xaviers-MacBook-Pro.local', 'ignore_result': False, 'replaced_task_nesting': 0, 'stamped_headers': None, 'stamps': {}}

The delivery info for this task is:
{'exchange': '', 'routing_key': 'heartbeat_bot'}
Traceback (most recent call last):
  File "/Library/Frameworks/Python.framework/Versions/3.12/lib/python3.12/site-packages/celery/worker/consumer/consumer.py", line 662, in on_task_received
    strategy = strategies[type_]
               ~~~~~~~~~~^^^^^^^
KeyError: 'backend.bot.tasks.collect_transactions'
[2025-10-16 07:27:20,110: ERROR/MainProcess] Received unregistered task of type 'backend.bot.tasks.collect_game_summaries'.
The message has been ignored and discarded.

Did you remember to import the module containing this task?
Or maybe you're using relative imports?

Please see
https://docs.celeryq.dev/en/latest/internals/protocol.html
for more information.

The full contents of the message body was:
b'[[], {}, {"callbacks": null, "errbacks": null, "chain": null, "chord": null}]' (77b)

The full contents of the message headers:
{'lang': 'py', 'task': 'backend.bot.tasks.collect_game_summaries', 'id': 'a52fd751-f315-4ebe-a7e6-9acf1e6b50c3', 'shadow': None, 'eta': None, 'expires': '2025-10-16T08:27:20.106908-04:00', 'group': None, 'group_index': None, 'retries': 0, 'timelimit': [None, None], 'root_id': 'a52fd751-f315-4ebe-a7e6-9acf1e6b50c3', 'parent_id': None, 'argsrepr': '()', 'kwargsrepr': '{}', 'origin': 'gen17308@Xaviers-MacBook-Pro.local', 'ignore_result': False, 'replaced_task_nesting': 0, 'stamped_headers': None, 'stamps': {}}

The delivery info for this task is:
{'exchange': '', 'routing_key': 'heartbeat_bot'}
Traceback (most recent call last):
  File "/Library/Frameworks/Python.framework/Versions/3.12/lib/python3.12/site-packages/celery/worker/consumer/consumer.py", line 662, in on_task_received
    strategy = strategies[type_]
               ~~~~~~~~~~^^^^^^^
KeyError: 'backend.bot.tasks.collect_game_summaries'
[2025-10-16 07:27:20,111: ERROR/MainProcess] Received unregistered task of type 'backend.bot.tasks.collect_team_news'.
The message has been ignored and discarded.

Did you remember to import the module containing this task?
Or maybe you're using relative imports?

Please see
https://docs.celeryq.dev/en/latest/internals/protocol.html
for more information.

The full contents of the message body was:
b'[[], {}, {"callbacks": null, "errbacks": null, "chain": null, "chord": null}]' (77b)

The full contents of the message headers:
{'lang': 'py', 'task': 'backend.bot.tasks.collect_team_news', 'id': 'a293a163-6a1e-4343-b33c-35c03091d71f', 'shadow': None, 'eta': None, 'expires': '2025-10-16T08:27:20.108104-04:00', 'group': None, 'group_index': None, 'retries': 0, 'timelimit': [None, None], 'root_id': 'a293a163-6a1e-4343-b33c-35c03091d71f', 'parent_id': None, 'argsrepr': '()', 'kwargsrepr': '{}', 'origin': 'gen17308@Xaviers-MacBook-Pro.local', 'ignore_result': False, 'replaced_task_nesting': 0, 'stamped_headers': None, 'stamps': {}}

The delivery info for this task is:
{'exchange': '', 'routing_key': 'heartbeat_bot'}
Traceback (most recent call last):
  File "/Library/Frameworks/Python.framework/Versions/3.12/lib/python3.12/site-packages/celery/worker/consumer/consumer.py", line 662, in on_task_received
    strategy = strategies[type_]
               ~~~~~~~~~~^^^^^^^
KeyError: 'backend.bot.tasks.collect_team_news'
[2025-10-16 07:27:20,112: ERROR/MainProcess] Received unregistered task of type 'backend.bot.tasks.collect_player_updates'.
The message has been ignored and discarded.

Did you remember to import the module containing this task?
Or maybe you're using relative imports?

Please see
https://docs.celeryq.dev/en/latest/internals/protocol.html
for more information.

The full contents of the message body was:
b'[[], {}, {"callbacks": null, "errbacks": null, "chain": null, "chord": null}]' (77b)

The full contents of the message headers:
{'lang': 'py', 'task': 'backend.bot.tasks.collect_player_updates', 'id': '7ee0e245-a419-4de7-b819-2dbd0c811dc1', 'shadow': None, 'eta': None, 'expires': '2025-10-16T08:27:20.109271-04:00', 'group': None, 'group_index': None, 'retries': 0, 'timelimit': [None, None], 'root_id': '7ee0e245-a419-4de7-b819-2dbd0c811dc1', 'parent_id': None, 'argsrepr': '()', 'kwargsrepr': '{}', 'origin': 'gen17308@Xaviers-MacBook-Pro.local', 'ignore_result': False, 'replaced_task_nesting': 0, 'stamped_headers': None, 'stamps': {}}

The delivery info for this task is:
{'exchange': '', 'routing_key': 'heartbeat_bot'}
Traceback (most recent call last):
  File "/Library/Frameworks/Python.framework/Versions/3.12/lib/python3.12/site-packages/celery/worker/consumer/consumer.py", line 662, in on_task_received
    strategy = strategies[type_]
               ~~~~~~~~~~^^^^^^^
KeyError: 'backend.bot.tasks.collect_player_updates'
[2025-10-16 07:27:20,114: ERROR/MainProcess] Received unregistered task of type 'backend.bot.tasks.generate_daily_article'.
The message has been ignored and discarded.

Did you remember to import the module containing this task?
Or maybe you're using relative imports?

Please see
https://docs.celeryq.dev/en/latest/internals/protocol.html
for more information.

The full contents of the message body was:
b'[[], {}, {"callbacks": null, "errbacks": null, "chain": null, "chord": null}]' (77b)

The full contents of the message headers:
{'lang': 'py', 'task': 'backend.bot.tasks.generate_daily_article', 'id': '96c0ed54-d590-494d-b8f6-b60450855ad2', 'shadow': None, 'eta': None, 'expires': '2025-10-16T08:27:20.110445-04:00', 'group': None, 'group_index': None, 'retries': 0, 'timelimit': [None, None], 'root_id': '96c0ed54-d590-494d-b8f6-b60450855ad2', 'parent_id': None, 'argsrepr': '()', 'kwargsrepr': '{}', 'origin': 'gen17308@Xaviers-MacBook-Pro.local', 'ignore_result': False, 'replaced_task_nesting': 0, 'stamped_headers': None, 'stamps': {}}

The delivery info for this task is:
{'exchange': '', 'routing_key': 'heartbeat_bot'}
Traceback (most recent call last):
  File "/Library/Frameworks/Python.framework/Versions/3.12/lib/python3.12/site-packages/celery/worker/consumer/consumer.py", line 662, in on_task_received
    strategy = strategies[type_]
               ~~~~~~~~~~^^^^^^^
KeyError: 'backend.bot.tasks.generate_daily_article'
[2025-10-16 10:03:39,455: ERROR/MainProcess] Received unregistered task of type 'backend.bot.tasks.collect_transactions'.
The message has been ignored and discarded.

Did you remember to import the module containing this task?
Or maybe you're using relative imports?

Please see
https://docs.celeryq.dev/en/latest/internals/protocol.html
for more information.

The full contents of the message body was:
b'[[], {}, {"callbacks": null, "errbacks": null, "chain": null, "chord": null}]' (77b)

The full contents of the message headers:
{'lang': 'py', 'task': 'backend.bot.tasks.collect_transactions', 'id': '2ab4e328-4882-42c5-825a-80b274374b0d', 'shadow': None, 'eta': None, 'expires': '2025-10-16T10:28:39.447363-04:00', 'group': None, 'group_index': None, 'retries': 0, 'timelimit': [None, None], 'root_id': '2ab4e328-4882-42c5-825a-80b274374b0d', 'parent_id': None, 'argsrepr': '()', 'kwargsrepr': '{}', 'origin': 'gen17308@Xaviers-MacBook-Pro.local', 'ignore_result': False, 'replaced_task_nesting': 0, 'stamped_headers': None, 'stamps': {}}

The delivery info for this task is:
{'exchange': '', 'routing_key': 'heartbeat_bot'}
Traceback (most recent call last):
  File "/Library/Frameworks/Python.framework/Versions/3.12/lib/python3.12/site-packages/celery/worker/consumer/consumer.py", line 662, in on_task_received
    strategy = strategies[type_]
               ~~~~~~~~~~^^^^^^^
KeyError: 'backend.bot.tasks.collect_transactions'
[2025-10-16 10:13:48,970: INFO/MainProcess] Connected to redis://localhost:6379/0
[2025-10-16 10:13:48,971: INFO/MainProcess] mingle: searching for neighbors
[2025-10-16 10:13:50,000: INFO/MainProcess] mingle: all alone
[2025-10-16 10:13:50,021: INFO/MainProcess] celery@Mac ready.
[2025-10-16 10:30:00,088: ERROR/MainProcess] Received unregistered task of type 'backend.bot.tasks.collect_transactions'.
The message has been ignored and discarded.

Did you remember to import the module containing this task?
Or maybe you're using relative imports?

Please see
https://docs.celeryq.dev/en/latest/internals/protocol.html
for more information.

The full contents of the message body was:
b'[[], {}, {"callbacks": null, "errbacks": null, "chain": null, "chord": null}]' (77b)

The full contents of the message headers:
{'lang': 'py', 'task': 'backend.bot.tasks.collect_transactions', 'id': '0094527a-cc22-4edf-8cb0-7b109c616899', 'shadow': None, 'eta': None, 'expires': '2025-10-16T10:55:00.064341-04:00', 'group': None, 'group_index': None, 'retries': 0, 'timelimit': [None, None], 'root_id': '0094527a-cc22-4edf-8cb0-7b109c616899', 'parent_id': None, 'argsrepr': '()', 'kwargsrepr': '{}', 'origin': 'gen42345@Mac', 'ignore_result': False, 'replaced_task_nesting': 0, 'stamped_headers': None, 'stamps': {}}

The delivery info for this task is:
{'exchange': '', 'routing_key': 'heartbeat_bot'}
Traceback (most recent call last):
  File "/Library/Frameworks/Python.framework/Versions/3.12/lib/python3.12/site-packages/celery/worker/consumer/consumer.py", line 662, in on_task_received
    strategy = strategies[type_]
               ~~~~~~~~~~^^^^^^^
KeyError: 'backend.bot.tasks.collect_transactions'
[2025-10-16 11:00:00,058: ERROR/MainProcess] Received unregistered task of type 'backend.bot.tasks.collect_transactions'.
The message has been ignored and discarded.

Did you remember to import the module containing this task?
Or maybe you're using relative imports?

Please see
https://docs.celeryq.dev/en/latest/internals/protocol.html
for more information.

The full contents of the message body was:
b'[[], {}, {"callbacks": null, "errbacks": null, "chain": null, "chord": null}]' (77b)

The full contents of the message headers:
{'lang': 'py', 'task': 'backend.bot.tasks.collect_transactions', 'id': '27f970cc-20d1-41b4-816e-aa5bbd7072c1', 'shadow': None, 'eta': None, 'expires': '2025-10-16T11:25:00.019899-04:00', 'group': None, 'group_index': None, 'retries': 0, 'timelimit': [None, None], 'root_id': '27f970cc-20d1-41b4-816e-aa5bbd7072c1', 'parent_id': None, 'argsrepr': '()', 'kwargsrepr': '{}', 'origin': 'gen42345@Mac', 'ignore_result': False, 'replaced_task_nesting': 0, 'stamped_headers': None, 'stamps': {}}

The delivery info for this task is:
{'exchange': '', 'routing_key': 'heartbeat_bot'}
Traceback (most recent call last):
  File "/Library/Frameworks/Python.framework/Versions/3.12/lib/python3.12/site-packages/celery/worker/consumer/consumer.py", line 662, in on_task_received
    strategy = strategies[type_]
               ~~~~~~~~~~^^^^^^^
KeyError: 'backend.bot.tasks.collect_transactions'
[2025-10-16 11:30:00,039: ERROR/MainProcess] Received unregistered task of type 'backend.bot.tasks.collect_transactions'.
The message has been ignored and discarded.

Did you remember to import the module containing this task?
Or maybe you're using relative imports?

Please see
https://docs.celeryq.dev/en/latest/internals/protocol.html
for more information.

The full contents of the message body was:
b'[[], {}, {"callbacks": null, "errbacks": null, "chain": null, "chord": null}]' (77b)

The full contents of the message headers:
{'lang': 'py', 'task': 'backend.bot.tasks.collect_transactions', 'id': '2096f44e-ddb3-4596-bd62-d1b796581e51', 'shadow': None, 'eta': None, 'expires': '2025-10-16T11:55:00.016569-04:00', 'group': None, 'group_index': None, 'retries': 0, 'timelimit': [None, None], 'root_id': '2096f44e-ddb3-4596-bd62-d1b796581e51', 'parent_id': None, 'argsrepr': '()', 'kwargsrepr': '{}', 'origin': 'gen42345@Mac', 'ignore_result': False, 'replaced_task_nesting': 0, 'stamped_headers': None, 'stamps': {}}

The delivery info for this task is:
{'exchange': '', 'routing_key': 'heartbeat_bot'}
Traceback (most recent call last):
  File "/Library/Frameworks/Python.framework/Versions/3.12/lib/python3.12/site-packages/celery/worker/consumer/consumer.py", line 662, in on_task_received
    strategy = strategies[type_]
               ~~~~~~~~~~^^^^^^^
KeyError: 'backend.bot.tasks.collect_transactions'
[2025-10-16 12:00:00,064: ERROR/MainProcess] Received unregistered task of type 'backend.bot.tasks.aggregate_and_synthesize_news'.
The message has been ignored and discarded.

Did you remember to import the module containing this task?
Or maybe you're using relative imports?

Please see
https://docs.celeryq.dev/en/latest/internals/protocol.html
for more information.

The full contents of the message body was:
b'[[], {}, {"callbacks": null, "errbacks": null, "chain": null, "chord": null}]' (77b)

The full contents of the message headers:
{'lang': 'py', 'task': 'backend.bot.tasks.aggregate_and_synthesize_news', 'id': 'adba7e1f-14b4-4bfc-a62b-f6c1394e6b00', 'shadow': None, 'eta': None, 'expires': '2025-10-16T17:00:00.027822-04:00', 'group': None, 'group_index': None, 'retries': 0, 'timelimit': [None, None], 'root_id': 'adba7e1f-14b4-4bfc-a62b-f6c1394e6b00', 'parent_id': None, 'argsrepr': '()', 'kwargsrepr': '{}', 'origin': 'gen42345@Mac', 'ignore_result': False, 'replaced_task_nesting': 0, 'stamped_headers': None, 'stamps': {}}

The delivery info for this task is:
{'exchange': '', 'routing_key': 'heartbeat_bot'}
Traceback (most recent call last):
  File "/Library/Frameworks/Python.framework/Versions/3.12/lib/python3.12/site-packages/celery/worker/consumer/consumer.py", line 662, in on_task_received
    strategy = strategies[type_]
               ~~~~~~~~~~^^^^^^^
KeyError: 'backend.bot.tasks.aggregate_and_synthesize_news'
[2025-10-16 12:00:00,089: ERROR/MainProcess] Received unregistered task of type 'backend.bot.tasks.collect_transactions'.
The message has been ignored and discarded.

Did you remember to import the module containing this task?
Or maybe you're using relative imports?

Please see
https://docs.celeryq.dev/en/latest/internals/protocol.html
for more information.

The full contents of the message body was:
b'[[], {}, {"callbacks": null, "errbacks": null, "chain": null, "chord": null}]' (77b)

The full contents of the message headers:
{'lang': 'py', 'task': 'backend.bot.tasks.collect_transactions', 'id': '67a916fb-4205-4b2f-82f8-85dd7455bc84', 'shadow': None, 'eta': None, 'expires': '2025-10-16T12:25:00.052708-04:00', 'group': None, 'group_index': None, 'retries': 0, 'timelimit': [None, None], 'root_id': '67a916fb-4205-4b2f-82f8-85dd7455bc84', 'parent_id': None, 'argsrepr': '()', 'kwargsrepr': '{}', 'origin': 'gen42345@Mac', 'ignore_result': False, 'replaced_task_nesting': 0, 'stamped_headers': None, 'stamps': {}}

The delivery info for this task is:
{'exchange': '', 'routing_key': 'heartbeat_bot'}
Traceback (most recent call last):
  File "/Library/Frameworks/Python.framework/Versions/3.12/lib/python3.12/site-packages/celery/worker/consumer/consumer.py", line 662, in on_task_received
    strategy = strategies[type_]
               ~~~~~~~~~~^^^^^^^
KeyError: 'backend.bot.tasks.collect_transactions'
[2025-10-16 12:30:00,061: ERROR/MainProcess] Received unregistered task of type 'backend.bot.tasks.collect_transactions'.
The message has been ignored and discarded.

Did you remember to import the module containing this task?
Or maybe you're using relative imports?

Please see
https://docs.celeryq.dev/en/latest/internals/protocol.html
for more information.

The full contents of the message body was:
b'[[], {}, {"callbacks": null, "errbacks": null, "chain": null, "chord": null}]' (77b)

The full contents of the message headers:
{'lang': 'py', 'task': 'backend.bot.tasks.collect_transactions', 'id': 'c72dfc42-0e2e-49b0-9b40-39ad1efa5322', 'shadow': None, 'eta': None, 'expires': '2025-10-16T12:55:00.031350-04:00', 'group': None, 'group_index': None, 'retries': 0, 'timelimit': [None, None], 'root_id': 'c72dfc42-0e2e-49b0-9b40-39ad1efa5322', 'parent_id': None, 'argsrepr': '()', 'kwargsrepr': '{}', 'origin': 'gen42345@Mac', 'ignore_result': False, 'replaced_task_nesting': 0, 'stamped_headers': None, 'stamps': {}}

The delivery info for this task is:
{'exchange': '', 'routing_key': 'heartbeat_bot'}
Traceback (most recent call last):
  File "/Library/Frameworks/Python.framework/Versions/3.12/lib/python3.12/site-packages/celery/worker/consumer/consumer.py", line 662, in on_task_received
    strategy = strategies[type_]
               ~~~~~~~~~~^^^^^^^
KeyError: 'backend.bot.tasks.collect_transactions'
[2025-10-16 12:55:02,051: INFO/MainProcess] Connected to redis://localhost:6379/0
[2025-10-16 12:55:02,083: INFO/MainProcess] mingle: searching for neighbors
[2025-10-16 12:55:03,162: INFO/MainProcess] mingle: all alone
[2025-10-16 12:55:03,297: INFO/MainProcess] celery@Mac ready.
[2025-10-16 13:00:00,137: ERROR/MainProcess] Received unregistered task of type 'backend.bot.tasks.collect_transactions'.
The message has been ignored and discarded.

Did you remember to import the module containing this task?
Or maybe you're using relative imports?

Please see
https://docs.celeryq.dev/en/latest/internals/protocol.html
for more information.

The full contents of the message body was:
b'[[], {}, {"callbacks": null, "errbacks": null, "chain": null, "chord": null}]' (77b)

The full contents of the message headers:
{'lang': 'py', 'task': 'backend.bot.tasks.collect_transactions', 'id': '21610eda-4669-4044-bd32-690d7a840701', 'shadow': None, 'eta': None, 'expires': '2025-10-16T13:25:00.104331-04:00', 'group': None, 'group_index': None, 'retries': 0, 'timelimit': [None, None], 'root_id': '21610eda-4669-4044-bd32-690d7a840701', 'parent_id': None, 'argsrepr': '()', 'kwargsrepr': '{}', 'origin': 'gen9535@Mac', 'ignore_result': False, 'replaced_task_nesting': 0, 'stamped_headers': None, 'stamps': {}}

The delivery info for this task is:
{'exchange': '', 'routing_key': 'heartbeat_bot'}
Traceback (most recent call last):
  File "/Library/Frameworks/Python.framework/Versions/3.12/lib/python3.12/site-packages/celery/worker/consumer/consumer.py", line 662, in on_task_received
    strategy = strategies[type_]
               ~~~~~~~~~~^^^^^^^
KeyError: 'backend.bot.tasks.collect_transactions'
[2025-10-16 13:09:01,532: INFO/MainProcess] Connected to redis://localhost:6379/0
[2025-10-16 13:09:01,534: INFO/MainProcess] mingle: searching for neighbors
[2025-10-16 13:09:02,563: INFO/MainProcess] mingle: all alone
[2025-10-16 13:09:02,623: INFO/MainProcess] celery@Mac ready.
[2025-10-16 14:30:44,656: ERROR/MainProcess] Received unregistered task of type 'backend.bot.tasks.collect_transactions'.
The message has been ignored and discarded.

Did you remember to import the module containing this task?
Or maybe you're using relative imports?

Please see
https://docs.celeryq.dev/en/latest/internals/protocol.html
for more information.

The full contents of the message body was:
b'[[], {}, {"callbacks": null, "errbacks": null, "chain": null, "chord": null}]' (77b)

The full contents of the message headers:
{'lang': 'py', 'task': 'backend.bot.tasks.collect_transactions', 'id': '2ed01004-b757-4443-9a5f-a8de75608817', 'shadow': None, 'eta': None, 'expires': '2025-10-16T14:55:44.641693-04:00', 'group': None, 'group_index': None, 'retries': 0, 'timelimit': [None, None], 'root_id': '2ed01004-b757-4443-9a5f-a8de75608817', 'parent_id': None, 'argsrepr': '()', 'kwargsrepr': '{}', 'origin': 'gen24235@Mac', 'ignore_result': False, 'replaced_task_nesting': 0, 'stamped_headers': None, 'stamps': {}}

The delivery info for this task is:
{'exchange': '', 'routing_key': 'heartbeat_bot'}
Traceback (most recent call last):
  File "/Library/Frameworks/Python.framework/Versions/3.12/lib/python3.12/site-packages/celery/worker/consumer/consumer.py", line 662, in on_task_received
    strategy = strategies[type_]
               ~~~~~~~~~~^^^^^^^
KeyError: 'backend.bot.tasks.collect_transactions'
[2025-10-16 15:20:10,001: ERROR/MainProcess] Received unregistered task of type 'backend.bot.tasks.collect_transactions'.
The message has been ignored and discarded.

Did you remember to import the module containing this task?
Or maybe you're using relative imports?

Please see
https://docs.celeryq.dev/en/latest/internals/protocol.html
for more information.

The full contents of the message body was:
b'[[], {}, {"callbacks": null, "errbacks": null, "chain": null, "chord": null}]' (77b)

The full contents of the message headers:
{'lang': 'py', 'task': 'backend.bot.tasks.collect_transactions', 'id': '24913ab9-1f69-4efd-b764-7ff1cdc3069f', 'shadow': None, 'eta': None, 'expires': '2025-10-16T15:45:09.994697-04:00', 'group': None, 'group_index': None, 'retries': 0, 'timelimit': [None, None], 'root_id': '24913ab9-1f69-4efd-b764-7ff1cdc3069f', 'parent_id': None, 'argsrepr': '()', 'kwargsrepr': '{}', 'origin': 'gen24235@Mac', 'ignore_result': False, 'replaced_task_nesting': 0, 'stamped_headers': None, 'stamps': {}}

The delivery info for this task is:
{'exchange': '', 'routing_key': 'heartbeat_bot'}
Traceback (most recent call last):
  File "/Library/Frameworks/Python.framework/Versions/3.12/lib/python3.12/site-packages/celery/worker/consumer/consumer.py", line 662, in on_task_received
    strategy = strategies[type_]
               ~~~~~~~~~~^^^^^^^
KeyError: 'backend.bot.tasks.collect_transactions'
[2025-10-16 15:30:00,013: ERROR/MainProcess] Received unregistered task of type 'backend.bot.tasks.collect_transactions'.
The message has been ignored and discarded.

Did you remember to import the module containing this task?
Or maybe you're using relative imports?

Please see
https://docs.celeryq.dev/en/latest/internals/protocol.html
for more information.

The full contents of the message body was:
b'[[], {}, {"callbacks": null, "errbacks": null, "chain": null, "chord": null}]' (77b)

The full contents of the message headers:
{'lang': 'py', 'task': 'backend.bot.tasks.collect_transactions', 'id': '96108e4a-9369-4e9b-9f56-fa4a4564abd5', 'shadow': None, 'eta': None, 'expires': '2025-10-16T15:55:00.003030-04:00', 'group': None, 'group_index': None, 'retries': 0, 'timelimit': [None, None], 'root_id': '96108e4a-9369-4e9b-9f56-fa4a4564abd5', 'parent_id': None, 'argsrepr': '()', 'kwargsrepr': '{}', 'origin': 'gen24235@Mac', 'ignore_result': False, 'replaced_task_nesting': 0, 'stamped_headers': None, 'stamps': {}}

The delivery info for this task is:
{'exchange': '', 'routing_key': 'heartbeat_bot'}
Traceback (most recent call last):
  File "/Library/Frameworks/Python.framework/Versions/3.12/lib/python3.12/site-packages/celery/worker/consumer/consumer.py", line 662, in on_task_received
    strategy = strategies[type_]
               ~~~~~~~~~~^^^^^^^
KeyError: 'backend.bot.tasks.collect_transactions'
[2025-10-16 16:00:00,026: ERROR/MainProcess] Received unregistered task of type 'backend.bot.tasks.collect_transactions'.
The message has been ignored and discarded.

Did you remember to import the module containing this task?
Or maybe you're using relative imports?

Please see
https://docs.celeryq.dev/en/latest/internals/protocol.html
for more information.

The full contents of the message body was:
b'[[], {}, {"callbacks": null, "errbacks": null, "chain": null, "chord": null}]' (77b)

The full contents of the message headers:
{'lang': 'py', 'task': 'backend.bot.tasks.collect_transactions', 'id': '9cd6667b-d95e-4735-b959-0c2cfa41594f', 'shadow': None, 'eta': None, 'expires': '2025-10-16T16:25:00.009340-04:00', 'group': None, 'group_index': None, 'retries': 0, 'timelimit': [None, None], 'root_id': '9cd6667b-d95e-4735-b959-0c2cfa41594f', 'parent_id': None, 'argsrepr': '()', 'kwargsrepr': '{}', 'origin': 'gen24235@Mac', 'ignore_result': False, 'replaced_task_nesting': 0, 'stamped_headers': None, 'stamps': {}}

The delivery info for this task is:
{'exchange': '', 'routing_key': 'heartbeat_bot'}
Traceback (most recent call last):
  File "/Library/Frameworks/Python.framework/Versions/3.12/lib/python3.12/site-packages/celery/worker/consumer/consumer.py", line 662, in on_task_received
    strategy = strategies[type_]
               ~~~~~~~~~~^^^^^^^
KeyError: 'backend.bot.tasks.collect_transactions'
[2025-10-16 16:30:00,030: ERROR/MainProcess] Received unregistered task of type 'backend.bot.tasks.collect_transactions'.
The message has been ignored and discarded.

Did you remember to import the module containing this task?
Or maybe you're using relative imports?

Please see
https://docs.celeryq.dev/en/latest/internals/protocol.html
for more information.

The full contents of the message body was:
b'[[], {}, {"callbacks": null, "errbacks": null, "chain": null, "chord": null}]' (77b)

The full contents of the message headers:
{'lang': 'py', 'task': 'backend.bot.tasks.collect_transactions', 'id': '0536b017-d25a-4cc9-b167-748e12bfa9cd', 'shadow': None, 'eta': None, 'expires': '2025-10-16T16:55:00.019093-04:00', 'group': None, 'group_index': None, 'retries': 0, 'timelimit': [None, None], 'root_id': '0536b017-d25a-4cc9-b167-748e12bfa9cd', 'parent_id': None, 'argsrepr': '()', 'kwargsrepr': '{}', 'origin': 'gen24235@Mac', 'ignore_result': False, 'replaced_task_nesting': 0, 'stamped_headers': None, 'stamps': {}}

The delivery info for this task is:
{'exchange': '', 'routing_key': 'heartbeat_bot'}
Traceback (most recent call last):
  File "/Library/Frameworks/Python.framework/Versions/3.12/lib/python3.12/site-packages/celery/worker/consumer/consumer.py", line 662, in on_task_received
    strategy = strategies[type_]
               ~~~~~~~~~~^^^^^^^
KeyError: 'backend.bot.tasks.collect_transactions'
[2025-10-16 17:00:00,017: ERROR/MainProcess] Received unregistered task of type 'backend.bot.tasks.collect_transactions'.
The message has been ignored and discarded.

Did you remember to import the module containing this task?
Or maybe you're using relative imports?

Please see
https://docs.celeryq.dev/en/latest/internals/protocol.html
for more information.

The full contents of the message body was:
b'[[], {}, {"callbacks": null, "errbacks": null, "chain": null, "chord": null}]' (77b)

The full contents of the message headers:
{'lang': 'py', 'task': 'backend.bot.tasks.collect_transactions', 'id': 'bf036cae-72dc-47c0-96bf-3ed4a48e4e4f', 'shadow': None, 'eta': None, 'expires': '2025-10-16T17:25:00.005950-04:00', 'group': None, 'group_index': None, 'retries': 0, 'timelimit': [None, None], 'root_id': 'bf036cae-72dc-47c0-96bf-3ed4a48e4e4f', 'parent_id': None, 'argsrepr': '()', 'kwargsrepr': '{}', 'origin': 'gen24235@Mac', 'ignore_result': False, 'replaced_task_nesting': 0, 'stamped_headers': None, 'stamps': {}}

The delivery info for this task is:
{'exchange': '', 'routing_key': 'heartbeat_bot'}
Traceback (most recent call last):
  File "/Library/Frameworks/Python.framework/Versions/3.12/lib/python3.12/site-packages/celery/worker/consumer/consumer.py", line 662, in on_task_received
    strategy = strategies[type_]
               ~~~~~~~~~~^^^^^^^
KeyError: 'backend.bot.tasks.collect_transactions'
[2025-10-16 20:13:15,448: ERROR/MainProcess] Received unregistered task of type 'backend.bot.tasks.collect_transactions'.
The message has been ignored and discarded.

Did you remember to import the module containing this task?
Or maybe you're using relative imports?

Please see
https://docs.celeryq.dev/en/latest/internals/protocol.html
for more information.

The full contents of the message body was:
b'[[], {}, {"callbacks": null, "errbacks": null, "chain": null, "chord": null}]' (77b)

The full contents of the message headers:
{'lang': 'py', 'task': 'backend.bot.tasks.collect_transactions', 'id': '5a6d83fc-cf50-452f-b805-faaa0ecc905a', 'shadow': None, 'eta': None, 'expires': '2025-10-16T20:38:15.438746-04:00', 'group': None, 'group_index': None, 'retries': 0, 'timelimit': [None, None], 'root_id': '5a6d83fc-cf50-452f-b805-faaa0ecc905a', 'parent_id': None, 'argsrepr': '()', 'kwargsrepr': '{}', 'origin': 'gen24235@Mac', 'ignore_result': False, 'replaced_task_nesting': 0, 'stamped_headers': None, 'stamps': {}}

The delivery info for this task is:
{'exchange': '', 'routing_key': 'heartbeat_bot'}
Traceback (most recent call last):
  File "/Library/Frameworks/Python.framework/Versions/3.12/lib/python3.12/site-packages/celery/worker/consumer/consumer.py", line 662, in on_task_received
    strategy = strategies[type_]
               ~~~~~~~~~~^^^^^^^
KeyError: 'backend.bot.tasks.collect_transactions'
[2025-10-16 20:13:15,465: ERROR/MainProcess] Received unregistered task of type 'backend.bot.tasks.collect_injury_reports'.
The message has been ignored and discarded.

Did you remember to import the module containing this task?
Or maybe you're using relative imports?

Please see
https://docs.celeryq.dev/en/latest/internals/protocol.html
for more information.

The full contents of the message body was:
b'[[], {}, {"callbacks": null, "errbacks": null, "chain": null, "chord": null}]' (77b)

The full contents of the message headers:
{'lang': 'py', 'task': 'backend.bot.tasks.collect_injury_reports', 'id': '3de71af0-eb99-4a2d-91bf-207349f9a0f7', 'shadow': None, 'eta': None, 'expires': '2025-10-17T01:13:15.446015-04:00', 'group': None, 'group_index': None, 'retries': 0, 'timelimit': [None, None], 'root_id': '3de71af0-eb99-4a2d-91bf-207349f9a0f7', 'parent_id': None, 'argsrepr': '()', 'kwargsrepr': '{}', 'origin': 'gen24235@Mac', 'ignore_result': False, 'replaced_task_nesting': 0, 'stamped_headers': None, 'stamps': {}}

The delivery info for this task is:
{'exchange': '', 'routing_key': 'heartbeat_bot'}
Traceback (most recent call last):
  File "/Library/Frameworks/Python.framework/Versions/3.12/lib/python3.12/site-packages/celery/worker/consumer/consumer.py", line 662, in on_task_received
    strategy = strategies[type_]
               ~~~~~~~~~~^^^^^^^
KeyError: 'backend.bot.tasks.collect_injury_reports'
[2025-10-16 20:13:15,470: ERROR/MainProcess] Received unregistered task of type 'backend.bot.tasks.aggregate_and_synthesize_news'.
The message has been ignored and discarded.

Did you remember to import the module containing this task?
Or maybe you're using relative imports?

Please see
https://docs.celeryq.dev/en/latest/internals/protocol.html
for more information.

The full contents of the message body was:
b'[[], {}, {"callbacks": null, "errbacks": null, "chain": null, "chord": null}]' (77b)

The full contents of the message headers:
{'lang': 'py', 'task': 'backend.bot.tasks.aggregate_and_synthesize_news', 'id': '73b753b5-e4a9-4e40-b056-823daad59700', 'shadow': None, 'eta': None, 'expires': '2025-10-17T01:13:15.449130-04:00', 'group': None, 'group_index': None, 'retries': 0, 'timelimit': [None, None], 'root_id': '73b753b5-e4a9-4e40-b056-823daad59700', 'parent_id': None, 'argsrepr': '()', 'kwargsrepr': '{}', 'origin': 'gen24235@Mac', 'ignore_result': False, 'replaced_task_nesting': 0, 'stamped_headers': None, 'stamps': {}}

The delivery info for this task is:
{'exchange': '', 'routing_key': 'heartbeat_bot'}
Traceback (most recent call last):
  File "/Library/Frameworks/Python.framework/Versions/3.12/lib/python3.12/site-packages/celery/worker/consumer/consumer.py", line 662, in on_task_received
    strategy = strategies[type_]
               ~~~~~~~~~~^^^^^^^
KeyError: 'backend.bot.tasks.aggregate_and_synthesize_news'
[2025-10-16 20:30:00,017: ERROR/MainProcess] Received unregistered task of type 'backend.bot.tasks.collect_transactions'.
The message has been ignored and discarded.

Did you remember to import the module containing this task?
Or maybe you're using relative imports?

Please see
https://docs.celeryq.dev/en/latest/internals/protocol.html
for more information.

The full contents of the message body was:
b'[[], {}, {"callbacks": null, "errbacks": null, "chain": null, "chord": null}]' (77b)

The full contents of the message headers:
{'lang': 'py', 'task': 'backend.bot.tasks.collect_transactions', 'id': '616a8f7a-1bba-4928-bc18-b3b5e00252b2', 'shadow': None, 'eta': None, 'expires': '2025-10-16T20:55:00.009171-04:00', 'group': None, 'group_index': None, 'retries': 0, 'timelimit': [None, None], 'root_id': '616a8f7a-1bba-4928-bc18-b3b5e00252b2', 'parent_id': None, 'argsrepr': '()', 'kwargsrepr': '{}', 'origin': 'gen24235@Mac', 'ignore_result': False, 'replaced_task_nesting': 0, 'stamped_headers': None, 'stamps': {}}

The delivery info for this task is:
{'exchange': '', 'routing_key': 'heartbeat_bot'}
Traceback (most recent call last):
  File "/Library/Frameworks/Python.framework/Versions/3.12/lib/python3.12/site-packages/celery/worker/consumer/consumer.py", line 662, in on_task_received
    strategy = strategies[type_]
               ~~~~~~~~~~^^^^^^^
KeyError: 'backend.bot.tasks.collect_transactions'
[2025-10-16 21:00:00,009: ERROR/MainProcess] Received unregistered task of type 'backend.bot.tasks.collect_transactions'.
The message has been ignored and discarded.

Did you remember to import the module containing this task?
Or maybe you're using relative imports?

Please see
https://docs.celeryq.dev/en/latest/internals/protocol.html
for more information.

The full contents of the message body was:
b'[[], {}, {"callbacks": null, "errbacks": null, "chain": null, "chord": null}]' (77b)

The full contents of the message headers:
{'lang': 'py', 'task': 'backend.bot.tasks.collect_transactions', 'id': 'f95bdbdd-2412-4b79-b248-476df0ab9e38', 'shadow': None, 'eta': None, 'expires': '2025-10-16T21:25:00.005546-04:00', 'group': None, 'group_index': None, 'retries': 0, 'timelimit': [None, None], 'root_id': 'f95bdbdd-2412-4b79-b248-476df0ab9e38', 'parent_id': None, 'argsrepr': '()', 'kwargsrepr': '{}', 'origin': 'gen24235@Mac', 'ignore_result': False, 'replaced_task_nesting': 0, 'stamped_headers': None, 'stamps': {}}

The delivery info for this task is:
{'exchange': '', 'routing_key': 'heartbeat_bot'}
Traceback (most recent call last):
  File "/Library/Frameworks/Python.framework/Versions/3.12/lib/python3.12/site-packages/celery/worker/consumer/consumer.py", line 662, in on_task_received
    strategy = strategies[type_]
               ~~~~~~~~~~^^^^^^^
KeyError: 'backend.bot.tasks.collect_transactions'
[2025-10-16 21:30:00,013: ERROR/MainProcess] Received unregistered task of type 'backend.bot.tasks.collect_transactions'.
The message has been ignored and discarded.

Did you remember to import the module containing this task?
Or maybe you're using relative imports?

Please see
https://docs.celeryq.dev/en/latest/internals/protocol.html
for more information.

The full contents of the message body was:
b'[[], {}, {"callbacks": null, "errbacks": null, "chain": null, "chord": null}]' (77b)

The full contents of the message headers:
{'lang': 'py', 'task': 'backend.bot.tasks.collect_transactions', 'id': '01258945-45b0-46d3-ac23-49166da2c435', 'shadow': None, 'eta': None, 'expires': '2025-10-16T21:55:00.008002-04:00', 'group': None, 'group_index': None, 'retries': 0, 'timelimit': [None, None], 'root_id': '01258945-45b0-46d3-ac23-49166da2c435', 'parent_id': None, 'argsrepr': '()', 'kwargsrepr': '{}', 'origin': 'gen24235@Mac', 'ignore_result': False, 'replaced_task_nesting': 0, 'stamped_headers': None, 'stamps': {}}

The delivery info for this task is:
{'exchange': '', 'routing_key': 'heartbeat_bot'}
Traceback (most recent call last):
  File "/Library/Frameworks/Python.framework/Versions/3.12/lib/python3.12/site-packages/celery/worker/consumer/consumer.py", line 662, in on_task_received
    strategy = strategies[type_]
               ~~~~~~~~~~^^^^^^^
KeyError: 'backend.bot.tasks.collect_transactions'
[2025-10-16 22:00:00,015: ERROR/MainProcess] Received unregistered task of type 'backend.bot.tasks.collect_transactions'.
The message has been ignored and discarded.

Did you remember to import the module containing this task?
Or maybe you're using relative imports?

Please see
https://docs.celeryq.dev/en/latest/internals/protocol.html
for more information.

The full contents of the message body was:
b'[[], {}, {"callbacks": null, "errbacks": null, "chain": null, "chord": null}]' (77b)

The full contents of the message headers:
{'lang': 'py', 'task': 'backend.bot.tasks.collect_transactions', 'id': '19beb508-08ec-4616-9ef1-2cfe0c48a225', 'shadow': None, 'eta': None, 'expires': '2025-10-16T22:25:00.009632-04:00', 'group': None, 'group_index': None, 'retries': 0, 'timelimit': [None, None], 'root_id': '19beb508-08ec-4616-9ef1-2cfe0c48a225', 'parent_id': None, 'argsrepr': '()', 'kwargsrepr': '{}', 'origin': 'gen24235@Mac', 'ignore_result': False, 'replaced_task_nesting': 0, 'stamped_headers': None, 'stamps': {}}

The delivery info for this task is:
{'exchange': '', 'routing_key': 'heartbeat_bot'}
Traceback (most recent call last):
  File "/Library/Frameworks/Python.framework/Versions/3.12/lib/python3.12/site-packages/celery/worker/consumer/consumer.py", line 662, in on_task_received
    strategy = strategies[type_]
               ~~~~~~~~~~^^^^^^^
KeyError: 'backend.bot.tasks.collect_transactions'
[2025-10-17 08:35:39,207: ERROR/MainProcess] Received unregistered task of type 'backend.bot.tasks.collect_transactions'.
The message has been ignored and discarded.

Did you remember to import the module containing this task?
Or maybe you're using relative imports?

Please see
https://docs.celeryq.dev/en/latest/internals/protocol.html
for more information.

The full contents of the message body was:
b'[[], {}, {"callbacks": null, "errbacks": null, "chain": null, "chord": null}]' (77b)

The full contents of the message headers:
{'lang': 'py', 'task': 'backend.bot.tasks.collect_transactions', 'id': '41156404-18a9-4097-b6d2-44848999b096', 'shadow': None, 'eta': None, 'expires': '2025-10-17T09:00:39.188517-04:00', 'group': None, 'group_index': None, 'retries': 0, 'timelimit': [None, None], 'root_id': '41156404-18a9-4097-b6d2-44848999b096', 'parent_id': None, 'argsrepr': '()', 'kwargsrepr': '{}', 'origin': 'gen24235@Mac', 'ignore_result': False, 'replaced_task_nesting': 0, 'stamped_headers': None, 'stamps': {}}

The delivery info for this task is:
{'exchange': '', 'routing_key': 'heartbeat_bot'}
Traceback (most recent call last):
  File "/Library/Frameworks/Python.framework/Versions/3.12/lib/python3.12/site-packages/celery/worker/consumer/consumer.py", line 662, in on_task_received
    strategy = strategies[type_]
               ~~~~~~~~~~^^^^^^^
KeyError: 'backend.bot.tasks.collect_transactions'
[2025-10-17 08:35:39,213: ERROR/MainProcess] Received unregistered task of type 'backend.bot.tasks.collect_injury_reports'.
The message has been ignored and discarded.

Did you remember to import the module containing this task?
Or maybe you're using relative imports?

Please see
https://docs.celeryq.dev/en/latest/internals/protocol.html
for more information.

The full contents of the message body was:
b'[[], {}, {"callbacks": null, "errbacks": null, "chain": null, "chord": null}]' (77b)

The full contents of the message headers:
{'lang': 'py', 'task': 'backend.bot.tasks.collect_injury_reports', 'id': 'd8355e86-c87f-4a97-bea5-10a5c8fbc731', 'shadow': None, 'eta': None, 'expires': '2025-10-17T13:35:39.210695-04:00', 'group': None, 'group_index': None, 'retries': 0, 'timelimit': [None, None], 'root_id': 'd8355e86-c87f-4a97-bea5-10a5c8fbc731', 'parent_id': None, 'argsrepr': '()', 'kwargsrepr': '{}', 'origin': 'gen24235@Mac', 'ignore_result': False, 'replaced_task_nesting': 0, 'stamped_headers': None, 'stamps': {}}

The delivery info for this task is:
{'exchange': '', 'routing_key': 'heartbeat_bot'}
Traceback (most recent call last):
  File "/Library/Frameworks/Python.framework/Versions/3.12/lib/python3.12/site-packages/celery/worker/consumer/consumer.py", line 662, in on_task_received
    strategy = strategies[type_]
               ~~~~~~~~~~^^^^^^^
KeyError: 'backend.bot.tasks.collect_injury_reports'
[2025-10-17 08:35:39,214: ERROR/MainProcess] Received unregistered task of type 'backend.bot.tasks.aggregate_and_synthesize_news'.
The message has been ignored and discarded.

Did you remember to import the module containing this task?
Or maybe you're using relative imports?

Please see
https://docs.celeryq.dev/en/latest/internals/protocol.html
for more information.

The full contents of the message body was:
b'[[], {}, {"callbacks": null, "errbacks": null, "chain": null, "chord": null}]' (77b)

The full contents of the message headers:
{'lang': 'py', 'task': 'backend.bot.tasks.aggregate_and_synthesize_news', 'id': '317ef424-f180-4536-8bdc-0934baf0ea4a', 'shadow': None, 'eta': None, 'expires': '2025-10-17T13:35:39.211647-04:00', 'group': None, 'group_index': None, 'retries': 0, 'timelimit': [None, None], 'root_id': '317ef424-f180-4536-8bdc-0934baf0ea4a', 'parent_id': None, 'argsrepr': '()', 'kwargsrepr': '{}', 'origin': 'gen24235@Mac', 'ignore_result': False, 'replaced_task_nesting': 0, 'stamped_headers': None, 'stamps': {}}

The delivery info for this task is:
{'exchange': '', 'routing_key': 'heartbeat_bot'}
Traceback (most recent call last):
  File "/Library/Frameworks/Python.framework/Versions/3.12/lib/python3.12/site-packages/celery/worker/consumer/consumer.py", line 662, in on_task_received
    strategy = strategies[type_]
               ~~~~~~~~~~^^^^^^^
KeyError: 'backend.bot.tasks.aggregate_and_synthesize_news'
[2025-10-17 08:35:39,215: ERROR/MainProcess] Received unregistered task of type 'backend.bot.tasks.collect_game_summaries'.
The message has been ignored and discarded.

Did you remember to import the module containing this task?
Or maybe you're using relative imports?

Please see
https://docs.celeryq.dev/en/latest/internals/protocol.html
for more information.

The full contents of the message body was:
b'[[], {}, {"callbacks": null, "errbacks": null, "chain": null, "chord": null}]' (77b)

The full contents of the message headers:
{'lang': 'py', 'task': 'backend.bot.tasks.collect_game_summaries', 'id': '4af0f693-f5ee-427f-b15f-600ac11c617a', 'shadow': None, 'eta': None, 'expires': '2025-10-17T09:35:39.212437-04:00', 'group': None, 'group_index': None, 'retries': 0, 'timelimit': [None, None], 'root_id': '4af0f693-f5ee-427f-b15f-600ac11c617a', 'parent_id': None, 'argsrepr': '()', 'kwargsrepr': '{}', 'origin': 'gen24235@Mac', 'ignore_result': False, 'replaced_task_nesting': 0, 'stamped_headers': None, 'stamps': {}}

The delivery info for this task is:
{'exchange': '', 'routing_key': 'heartbeat_bot'}
Traceback (most recent call last):
  File "/Library/Frameworks/Python.framework/Versions/3.12/lib/python3.12/site-packages/celery/worker/consumer/consumer.py", line 662, in on_task_received
    strategy = strategies[type_]
               ~~~~~~~~~~^^^^^^^
KeyError: 'backend.bot.tasks.collect_game_summaries'
[2025-10-17 08:35:39,216: ERROR/MainProcess] Received unregistered task of type 'backend.bot.tasks.collect_team_news'.
The message has been ignored and discarded.

Did you remember to import the module containing this task?
Or maybe you're using relative imports?

Please see
https://docs.celeryq.dev/en/latest/internals/protocol.html
for more information.

The full contents of the message body was:
b'[[], {}, {"callbacks": null, "errbacks": null, "chain": null, "chord": null}]' (77b)

The full contents of the message headers:
{'lang': 'py', 'task': 'backend.bot.tasks.collect_team_news', 'id': '89b7960b-6644-42c8-9448-4bde178617ed', 'shadow': None, 'eta': None, 'expires': '2025-10-17T09:35:39.213170-04:00', 'group': None, 'group_index': None, 'retries': 0, 'timelimit': [None, None], 'root_id': '89b7960b-6644-42c8-9448-4bde178617ed', 'parent_id': None, 'argsrepr': '()', 'kwargsrepr': '{}', 'origin': 'gen24235@Mac', 'ignore_result': False, 'replaced_task_nesting': 0, 'stamped_headers': None, 'stamps': {}}

The delivery info for this task is:
{'exchange': '', 'routing_key': 'heartbeat_bot'}
Traceback (most recent call last):
  File "/Library/Frameworks/Python.framework/Versions/3.12/lib/python3.12/site-packages/celery/worker/consumer/consumer.py", line 662, in on_task_received
    strategy = strategies[type_]
               ~~~~~~~~~~^^^^^^^
KeyError: 'backend.bot.tasks.collect_team_news'
[2025-10-17 08:35:39,217: ERROR/MainProcess] Received unregistered task of type 'backend.bot.tasks.collect_player_updates'.
The message has been ignored and discarded.

Did you remember to import the module containing this task?
Or maybe you're using relative imports?

Please see
https://docs.celeryq.dev/en/latest/internals/protocol.html
for more information.

The full contents of the message body was:
b'[[], {}, {"callbacks": null, "errbacks": null, "chain": null, "chord": null}]' (77b)

The full contents of the message headers:
{'lang': 'py', 'task': 'backend.bot.tasks.collect_player_updates', 'id': '3f7bcc96-61ed-4f9c-b474-7d6ef13b8a7e', 'shadow': None, 'eta': None, 'expires': '2025-10-17T09:35:39.215234-04:00', 'group': None, 'group_index': None, 'retries': 0, 'timelimit': [None, None], 'root_id': '3f7bcc96-61ed-4f9c-b474-7d6ef13b8a7e', 'parent_id': None, 'argsrepr': '()', 'kwargsrepr': '{}', 'origin': 'gen24235@Mac', 'ignore_result': False, 'replaced_task_nesting': 0, 'stamped_headers': None, 'stamps': {}}

The delivery info for this task is:
{'exchange': '', 'routing_key': 'heartbeat_bot'}
Traceback (most recent call last):
  File "/Library/Frameworks/Python.framework/Versions/3.12/lib/python3.12/site-packages/celery/worker/consumer/consumer.py", line 662, in on_task_received
    strategy = strategies[type_]
               ~~~~~~~~~~^^^^^^^
KeyError: 'backend.bot.tasks.collect_player_updates'
[2025-10-17 08:35:39,230: ERROR/MainProcess] Received unregistered task of type 'backend.bot.tasks.generate_daily_article'.
The message has been ignored and discarded.

Did you remember to import the module containing this task?
Or maybe you're using relative imports?

Please see
https://docs.celeryq.dev/en/latest/internals/protocol.html
for more information.

The full contents of the message body was:
b'[[], {}, {"callbacks": null, "errbacks": null, "chain": null, "chord": null}]' (77b)

The full contents of the message headers:
{'lang': 'py', 'task': 'backend.bot.tasks.generate_daily_article', 'id': 'f32bd4ba-e2aa-44ee-b5a8-89795fcfbe51', 'shadow': None, 'eta': None, 'expires': '2025-10-17T09:35:39.215874-04:00', 'group': None, 'group_index': None, 'retries': 0, 'timelimit': [None, None], 'root_id': 'f32bd4ba-e2aa-44ee-b5a8-89795fcfbe51', 'parent_id': None, 'argsrepr': '()', 'kwargsrepr': '{}', 'origin': 'gen24235@Mac', 'ignore_result': False, 'replaced_task_nesting': 0, 'stamped_headers': None, 'stamps': {}}

The delivery info for this task is:
{'exchange': '', 'routing_key': 'heartbeat_bot'}
Traceback (most recent call last):
  File "/Library/Frameworks/Python.framework/Versions/3.12/lib/python3.12/site-packages/celery/worker/consumer/consumer.py", line 662, in on_task_received
    strategy = strategies[type_]
               ~~~~~~~~~~^^^^^^^
KeyError: 'backend.bot.tasks.generate_daily_article'
[2025-10-17 09:38:26,330: ERROR/MainProcess] Received unregistered task of type 'backend.bot.tasks.collect_transactions'.
The message has been ignored and discarded.

Did you remember to import the module containing this task?
Or maybe you're using relative imports?

Please see
https://docs.celeryq.dev/en/latest/internals/protocol.html
for more information.

The full contents of the message body was:
b'[[], {}, {"callbacks": null, "errbacks": null, "chain": null, "chord": null}]' (77b)

The full contents of the message headers:
{'lang': 'py', 'task': 'backend.bot.tasks.collect_transactions', 'id': 'df4db00f-5231-4d80-99ba-163428e0cfbf', 'shadow': None, 'eta': None, 'expires': '2025-10-17T10:03:26.324746-04:00', 'group': None, 'group_index': None, 'retries': 0, 'timelimit': [None, None], 'root_id': 'df4db00f-5231-4d80-99ba-163428e0cfbf', 'parent_id': None, 'argsrepr': '()', 'kwargsrepr': '{}', 'origin': 'gen24235@Mac', 'ignore_result': False, 'replaced_task_nesting': 0, 'stamped_headers': None, 'stamps': {}}

The delivery info for this task is:
{'exchange': '', 'routing_key': 'heartbeat_bot'}
Traceback (most recent call last):
  File "/Library/Frameworks/Python.framework/Versions/3.12/lib/python3.12/site-packages/celery/worker/consumer/consumer.py", line 662, in on_task_received
    strategy = strategies[type_]
               ~~~~~~~~~~^^^^^^^
KeyError: 'backend.bot.tasks.collect_transactions'
[2025-10-17 10:00:00,004: ERROR/MainProcess] Received unregistered task of type 'backend.bot.tasks.collect_transactions'.
The message has been ignored and discarded.

Did you remember to import the module containing this task?
Or maybe you're using relative imports?

Please see
https://docs.celeryq.dev/en/latest/internals/protocol.html
for more information.

The full contents of the message body was:
b'[[], {}, {"callbacks": null, "errbacks": null, "chain": null, "chord": null}]' (77b)

The full contents of the message headers:
{'lang': 'py', 'task': 'backend.bot.tasks.collect_transactions', 'id': '1d27a421-ab52-4a9d-ba5c-18966b874277', 'shadow': None, 'eta': None, 'expires': '2025-10-17T10:25:00.002210-04:00', 'group': None, 'group_index': None, 'retries': 0, 'timelimit': [None, None], 'root_id': '1d27a421-ab52-4a9d-ba5c-18966b874277', 'parent_id': None, 'argsrepr': '()', 'kwargsrepr': '{}', 'origin': 'gen24235@Mac', 'ignore_result': False, 'replaced_task_nesting': 0, 'stamped_headers': None, 'stamps': {}}

The delivery info for this task is:
{'exchange': '', 'routing_key': 'heartbeat_bot'}
Traceback (most recent call last):
  File "/Library/Frameworks/Python.framework/Versions/3.12/lib/python3.12/site-packages/celery/worker/consumer/consumer.py", line 662, in on_task_received
    strategy = strategies[type_]
               ~~~~~~~~~~^^^^^^^
KeyError: 'backend.bot.tasks.collect_transactions'
[2025-10-17 10:30:00,182: ERROR/MainProcess] Received unregistered task of type 'backend.bot.tasks.collect_transactions'.
The message has been ignored and discarded.

Did you remember to import the module containing this task?
Or maybe you're using relative imports?

Please see
https://docs.celeryq.dev/en/latest/internals/protocol.html
for more information.

The full contents of the message body was:
b'[[], {}, {"callbacks": null, "errbacks": null, "chain": null, "chord": null}]' (77b)

The full contents of the message headers:
{'lang': 'py', 'task': 'backend.bot.tasks.collect_transactions', 'id': '0a3ef635-5f40-4056-b622-550269e87c76', 'shadow': None, 'eta': None, 'expires': '2025-10-17T10:55:00.178631-04:00', 'group': None, 'group_index': None, 'retries': 0, 'timelimit': [None, None], 'root_id': '0a3ef635-5f40-4056-b622-550269e87c76', 'parent_id': None, 'argsrepr': '()', 'kwargsrepr': '{}', 'origin': 'gen24235@Mac', 'ignore_result': False, 'replaced_task_nesting': 0, 'stamped_headers': None, 'stamps': {}}

The delivery info for this task is:
{'exchange': '', 'routing_key': 'heartbeat_bot'}
Traceback (most recent call last):
  File "/Library/Frameworks/Python.framework/Versions/3.12/lib/python3.12/site-packages/celery/worker/consumer/consumer.py", line 662, in on_task_received
    strategy = strategies[type_]
               ~~~~~~~~~~^^^^^^^
KeyError: 'backend.bot.tasks.collect_transactions'
[2025-10-17 11:00:00,067: ERROR/MainProcess] Received unregistered task of type 'backend.bot.tasks.collect_transactions'.
The message has been ignored and discarded.

Did you remember to import the module containing this task?
Or maybe you're using relative imports?

Please see
https://docs.celeryq.dev/en/latest/internals/protocol.html
for more information.

The full contents of the message body was:
b'[[], {}, {"callbacks": null, "errbacks": null, "chain": null, "chord": null}]' (77b)

The full contents of the message headers:
{'lang': 'py', 'task': 'backend.bot.tasks.collect_transactions', 'id': '31c2e718-f508-48ae-b102-2fc1b21a75be', 'shadow': None, 'eta': None, 'expires': '2025-10-17T11:25:00.008721-04:00', 'group': None, 'group_index': None, 'retries': 0, 'timelimit': [None, None], 'root_id': '31c2e718-f508-48ae-b102-2fc1b21a75be', 'parent_id': None, 'argsrepr': '()', 'kwargsrepr': '{}', 'origin': 'gen24235@Mac', 'ignore_result': False, 'replaced_task_nesting': 0, 'stamped_headers': None, 'stamps': {}}

The delivery info for this task is:
{'exchange': '', 'routing_key': 'heartbeat_bot'}
Traceback (most recent call last):
  File "/Library/Frameworks/Python.framework/Versions/3.12/lib/python3.12/site-packages/celery/worker/consumer/consumer.py", line 662, in on_task_received
    strategy = strategies[type_]
               ~~~~~~~~~~^^^^^^^
KeyError: 'backend.bot.tasks.collect_transactions'
[2025-10-17 11:08:37,276: INFO/MainProcess] Connected to redis://localhost:6379/0
[2025-10-17 11:08:37,279: INFO/MainProcess] mingle: searching for neighbors
[2025-10-17 11:08:38,384: INFO/MainProcess] mingle: all alone
[2025-10-17 11:08:38,483: INFO/MainProcess] celery@Xaviers-MacBook-Pro.local ready.
[2025-10-17 11:30:00,030: ERROR/MainProcess] Received unregistered task of type 'backend.bot.tasks.collect_transactions'.
The message has been ignored and discarded.

Did you remember to import the module containing this task?
Or maybe you're using relative imports?

Please see
https://docs.celeryq.dev/en/latest/internals/protocol.html
for more information.

The full contents of the message body was:
b'[[], {}, {"callbacks": null, "errbacks": null, "chain": null, "chord": null}]' (77b)

The full contents of the message headers:
{'lang': 'py', 'task': 'backend.bot.tasks.collect_transactions', 'id': '4577539e-9207-4392-8b8c-0de92facc805', 'shadow': None, 'eta': None, 'expires': '2025-10-17T11:55:00.019643-04:00', 'group': None, 'group_index': None, 'retries': 0, 'timelimit': [None, None], 'root_id': '4577539e-9207-4392-8b8c-0de92facc805', 'parent_id': None, 'argsrepr': '()', 'kwargsrepr': '{}', 'origin': 'gen92972@Xaviers-MacBook-Pro.local', 'ignore_result': False, 'replaced_task_nesting': 0, 'stamped_headers': None, 'stamps': {}}

The delivery info for this task is:
{'exchange': '', 'routing_key': 'heartbeat_bot'}
Traceback (most recent call last):
  File "/Library/Frameworks/Python.framework/Versions/3.12/lib/python3.12/site-packages/celery/worker/consumer/consumer.py", line 662, in on_task_received
    strategy = strategies[type_]
               ~~~~~~~~~~^^^^^^^
KeyError: 'backend.bot.tasks.collect_transactions'
[2025-10-17 12:00:00,015: ERROR/MainProcess] Received unregistered task of type 'backend.bot.tasks.collect_injury_reports'.
The message has been ignored and discarded.

Did you remember to import the module containing this task?
Or maybe you're using relative imports?

Please see
https://docs.celeryq.dev/en/latest/internals/protocol.html
for more information.

The full contents of the message body was:
b'[[], {}, {"callbacks": null, "errbacks": null, "chain": null, "chord": null}]' (77b)

The full contents of the message headers:
{'lang': 'py', 'task': 'backend.bot.tasks.collect_injury_reports', 'id': '20e9129d-3f62-4b73-8f74-aadda0da7d11', 'shadow': None, 'eta': None, 'expires': '2025-10-17T17:00:00.004249-04:00', 'group': None, 'group_index': None, 'retries': 0, 'timelimit': [None, None], 'root_id': '20e9129d-3f62-4b73-8f74-aadda0da7d11', 'parent_id': None, 'argsrepr': '()', 'kwargsrepr': '{}', 'origin': 'gen92972@Xaviers-MacBook-Pro.local', 'ignore_result': False, 'replaced_task_nesting': 0, 'stamped_headers': None, 'stamps': {}}

The delivery info for this task is:
{'exchange': '', 'routing_key': 'heartbeat_bot'}
Traceback (most recent call last):
  File "/Library/Frameworks/Python.framework/Versions/3.12/lib/python3.12/site-packages/celery/worker/consumer/consumer.py", line 662, in on_task_received
    strategy = strategies[type_]
               ~~~~~~~~~~^^^^^^^
KeyError: 'backend.bot.tasks.collect_injury_reports'
[2025-10-17 12:00:00,021: ERROR/MainProcess] Received unregistered task of type 'backend.bot.tasks.aggregate_and_synthesize_news'.
The message has been ignored and discarded.

Did you remember to import the module containing this task?
Or maybe you're using relative imports?

Please see
https://docs.celeryq.dev/en/latest/internals/protocol.html
for more information.

The full contents of the message body was:
b'[[], {}, {"callbacks": null, "errbacks": null, "chain": null, "chord": null}]' (77b)

The full contents of the message headers:
{'lang': 'py', 'task': 'backend.bot.tasks.aggregate_and_synthesize_news', 'id': '232969ba-e588-4a94-9886-f8c17d9f3d03', 'shadow': None, 'eta': None, 'expires': '2025-10-17T17:00:00.014529-04:00', 'group': None, 'group_index': None, 'retries': 0, 'timelimit': [None, None], 'root_id': '232969ba-e588-4a94-9886-f8c17d9f3d03', 'parent_id': None, 'argsrepr': '()', 'kwargsrepr': '{}', 'origin': 'gen92972@Xaviers-MacBook-Pro.local', 'ignore_result': False, 'replaced_task_nesting': 0, 'stamped_headers': None, 'stamps': {}}

The delivery info for this task is:
{'exchange': '', 'routing_key': 'heartbeat_bot'}
Traceback (most recent call last):
  File "/Library/Frameworks/Python.framework/Versions/3.12/lib/python3.12/site-packages/celery/worker/consumer/consumer.py", line 662, in on_task_received
    strategy = strategies[type_]
               ~~~~~~~~~~^^^^^^^
KeyError: 'backend.bot.tasks.aggregate_and_synthesize_news'
[2025-10-17 12:00:00,023: ERROR/MainProcess] Received unregistered task of type 'backend.bot.tasks.collect_transactions'.
The message has been ignored and discarded.

Did you remember to import the module containing this task?
Or maybe you're using relative imports?

Please see
https://docs.celeryq.dev/en/latest/internals/protocol.html
for more information.

The full contents of the message body was:
b'[[], {}, {"callbacks": null, "errbacks": null, "chain": null, "chord": null}]' (77b)

The full contents of the message headers:
{'lang': 'py', 'task': 'backend.bot.tasks.collect_transactions', 'id': '8b1df9e2-f2de-44a7-b45c-c5358d0dabba', 'shadow': None, 'eta': None, 'expires': '2025-10-17T12:25:00.016588-04:00', 'group': None, 'group_index': None, 'retries': 0, 'timelimit': [None, None], 'root_id': '8b1df9e2-f2de-44a7-b45c-c5358d0dabba', 'parent_id': None, 'argsrepr': '()', 'kwargsrepr': '{}', 'origin': 'gen92972@Xaviers-MacBook-Pro.local', 'ignore_result': False, 'replaced_task_nesting': 0, 'stamped_headers': None, 'stamps': {}}

The delivery info for this task is:
{'exchange': '', 'routing_key': 'heartbeat_bot'}
Traceback (most recent call last):
  File "/Library/Frameworks/Python.framework/Versions/3.12/lib/python3.12/site-packages/celery/worker/consumer/consumer.py", line 662, in on_task_received
    strategy = strategies[type_]
               ~~~~~~~~~~^^^^^^^
KeyError: 'backend.bot.tasks.collect_transactions'
[2025-10-17 12:30:00,028: ERROR/MainProcess] Received unregistered task of type 'backend.bot.tasks.collect_transactions'.
The message has been ignored and discarded.

Did you remember to import the module containing this task?
Or maybe you're using relative imports?

Please see
https://docs.celeryq.dev/en/latest/internals/protocol.html
for more information.

The full contents of the message body was:
b'[[], {}, {"callbacks": null, "errbacks": null, "chain": null, "chord": null}]' (77b)

The full contents of the message headers:
{'lang': 'py', 'task': 'backend.bot.tasks.collect_transactions', 'id': '471309c3-ad29-482e-96a8-c117aa95d721', 'shadow': None, 'eta': None, 'expires': '2025-10-17T12:55:00.011362-04:00', 'group': None, 'group_index': None, 'retries': 0, 'timelimit': [None, None], 'root_id': '471309c3-ad29-482e-96a8-c117aa95d721', 'parent_id': None, 'argsrepr': '()', 'kwargsrepr': '{}', 'origin': 'gen92972@Xaviers-MacBook-Pro.local', 'ignore_result': False, 'replaced_task_nesting': 0, 'stamped_headers': None, 'stamps': {}}

The delivery info for this task is:
{'exchange': '', 'routing_key': 'heartbeat_bot'}
Traceback (most recent call last):
  File "/Library/Frameworks/Python.framework/Versions/3.12/lib/python3.12/site-packages/celery/worker/consumer/consumer.py", line 662, in on_task_received
    strategy = strategies[type_]
               ~~~~~~~~~~^^^^^^^
KeyError: 'backend.bot.tasks.collect_transactions'
[2025-10-17 13:00:00,572: ERROR/MainProcess] Received unregistered task of type 'backend.bot.tasks.collect_transactions'.
The message has been ignored and discarded.

Did you remember to import the module containing this task?
Or maybe you're using relative imports?

Please see
https://docs.celeryq.dev/en/latest/internals/protocol.html
for more information.

The full contents of the message body was:
b'[[], {}, {"callbacks": null, "errbacks": null, "chain": null, "chord": null}]' (77b)

The full contents of the message headers:
{'lang': 'py', 'task': 'backend.bot.tasks.collect_transactions', 'id': 'd2f859fb-7a82-4e5c-afb0-36c84270374f', 'shadow': None, 'eta': None, 'expires': '2025-10-17T13:25:00.049285-04:00', 'group': None, 'group_index': None, 'retries': 0, 'timelimit': [None, None], 'root_id': 'd2f859fb-7a82-4e5c-afb0-36c84270374f', 'parent_id': None, 'argsrepr': '()', 'kwargsrepr': '{}', 'origin': 'gen92972@Xaviers-MacBook-Pro.local', 'ignore_result': False, 'replaced_task_nesting': 0, 'stamped_headers': None, 'stamps': {}}

The delivery info for this task is:
{'exchange': '', 'routing_key': 'heartbeat_bot'}
Traceback (most recent call last):
  File "/Library/Frameworks/Python.framework/Versions/3.12/lib/python3.12/site-packages/celery/worker/consumer/consumer.py", line 662, in on_task_received
    strategy = strategies[type_]
               ~~~~~~~~~~^^^^^^^
KeyError: 'backend.bot.tasks.collect_transactions'
[2025-10-17 14:33:11,842: ERROR/MainProcess] Received unregistered task of type 'backend.bot.tasks.collect_transactions'.
The message has been ignored and discarded.

Did you remember to import the module containing this task?
Or maybe you're using relative imports?

Please see
https://docs.celeryq.dev/en/latest/internals/protocol.html
for more information.

The full contents of the message body was:
b'[[], {}, {"callbacks": null, "errbacks": null, "chain": null, "chord": null}]' (77b)

The full contents of the message headers:
{'lang': 'py', 'task': 'backend.bot.tasks.collect_transactions', 'id': '555d47d7-59e6-4f58-a23b-6bcc5159ad30', 'shadow': None, 'eta': None, 'expires': '2025-10-17T14:58:11.833889-04:00', 'group': None, 'group_index': None, 'retries': 0, 'timelimit': [None, None], 'root_id': '555d47d7-59e6-4f58-a23b-6bcc5159ad30', 'parent_id': None, 'argsrepr': '()', 'kwargsrepr': '{}', 'origin': 'gen92972@Xaviers-MacBook-Pro.local', 'ignore_result': False, 'replaced_task_nesting': 0, 'stamped_headers': None, 'stamps': {}}

The delivery info for this task is:
{'exchange': '', 'routing_key': 'heartbeat_bot'}
Traceback (most recent call last):
  File "/Library/Frameworks/Python.framework/Versions/3.12/lib/python3.12/site-packages/celery/worker/consumer/consumer.py", line 662, in on_task_received
    strategy = strategies[type_]
               ~~~~~~~~~~^^^^^^^
KeyError: 'backend.bot.tasks.collect_transactions'
[2025-10-17 15:00:00,237: ERROR/MainProcess] Received unregistered task of type 'backend.bot.tasks.collect_transactions'.
The message has been ignored and discarded.

Did you remember to import the module containing this task?
Or maybe you're using relative imports?

Please see
https://docs.celeryq.dev/en/latest/internals/protocol.html
for more information.

The full contents of the message body was:
b'[[], {}, {"callbacks": null, "errbacks": null, "chain": null, "chord": null}]' (77b)

The full contents of the message headers:
{'lang': 'py', 'task': 'backend.bot.tasks.collect_transactions', 'id': '6784aa65-d5f6-47ca-a7f4-22d504a65f21', 'shadow': None, 'eta': None, 'expires': '2025-10-17T15:25:00.038592-04:00', 'group': None, 'group_index': None, 'retries': 0, 'timelimit': [None, None], 'root_id': '6784aa65-d5f6-47ca-a7f4-22d504a65f21', 'parent_id': None, 'argsrepr': '()', 'kwargsrepr': '{}', 'origin': 'gen92972@Xaviers-MacBook-Pro.local', 'ignore_result': False, 'replaced_task_nesting': 0, 'stamped_headers': None, 'stamps': {}}

The delivery info for this task is:
{'exchange': '', 'routing_key': 'heartbeat_bot'}
Traceback (most recent call last):
  File "/Library/Frameworks/Python.framework/Versions/3.12/lib/python3.12/site-packages/celery/worker/consumer/consumer.py", line 662, in on_task_received
    strategy = strategies[type_]
               ~~~~~~~~~~^^^^^^^
KeyError: 'backend.bot.tasks.collect_transactions'
[2025-10-17 15:30:00,019: ERROR/MainProcess] Received unregistered task of type 'backend.bot.tasks.collect_transactions'.
The message has been ignored and discarded.

Did you remember to import the module containing this task?
Or maybe you're using relative imports?

Please see
https://docs.celeryq.dev/en/latest/internals/protocol.html
for more information.

The full contents of the message body was:
b'[[], {}, {"callbacks": null, "errbacks": null, "chain": null, "chord": null}]' (77b)

The full contents of the message headers:
{'lang': 'py', 'task': 'backend.bot.tasks.collect_transactions', 'id': '306f11c1-3d90-4ae3-bda3-fedff4e9690c', 'shadow': None, 'eta': None, 'expires': '2025-10-17T15:55:00.010546-04:00', 'group': None, 'group_index': None, 'retries': 0, 'timelimit': [None, None], 'root_id': '306f11c1-3d90-4ae3-bda3-fedff4e9690c', 'parent_id': None, 'argsrepr': '()', 'kwargsrepr': '{}', 'origin': 'gen92972@Xaviers-MacBook-Pro.local', 'ignore_result': False, 'replaced_task_nesting': 0, 'stamped_headers': None, 'stamps': {}}

The delivery info for this task is:
{'exchange': '', 'routing_key': 'heartbeat_bot'}
Traceback (most recent call last):
  File "/Library/Frameworks/Python.framework/Versions/3.12/lib/python3.12/site-packages/celery/worker/consumer/consumer.py", line 662, in on_task_received
    strategy = strategies[type_]
               ~~~~~~~~~~^^^^^^^
KeyError: 'backend.bot.tasks.collect_transactions'
[2025-10-17 16:00:00,014: ERROR/MainProcess] Received unregistered task of type 'backend.bot.tasks.collect_transactions'.
The message has been ignored and discarded.

Did you remember to import the module containing this task?
Or maybe you're using relative imports?

Please see
https://docs.celeryq.dev/en/latest/internals/protocol.html
for more information.

The full contents of the message body was:
b'[[], {}, {"callbacks": null, "errbacks": null, "chain": null, "chord": null}]' (77b)

The full contents of the message headers:
{'lang': 'py', 'task': 'backend.bot.tasks.collect_transactions', 'id': 'f651f4d2-7389-4fea-bd21-caeddb02fee3', 'shadow': None, 'eta': None, 'expires': '2025-10-17T16:25:00.002305-04:00', 'group': None, 'group_index': None, 'retries': 0, 'timelimit': [None, None], 'root_id': 'f651f4d2-7389-4fea-bd21-caeddb02fee3', 'parent_id': None, 'argsrepr': '()', 'kwargsrepr': '{}', 'origin': 'gen92972@Xaviers-MacBook-Pro.local', 'ignore_result': False, 'replaced_task_nesting': 0, 'stamped_headers': None, 'stamps': {}}

The delivery info for this task is:
{'exchange': '', 'routing_key': 'heartbeat_bot'}
Traceback (most recent call last):
  File "/Library/Frameworks/Python.framework/Versions/3.12/lib/python3.12/site-packages/celery/worker/consumer/consumer.py", line 662, in on_task_received
    strategy = strategies[type_]
               ~~~~~~~~~~^^^^^^^
KeyError: 'backend.bot.tasks.collect_transactions'
[2025-10-17 16:11:06,011: INFO/MainProcess] Connected to redis://localhost:6379/0
[2025-10-17 16:11:06,013: INFO/MainProcess] mingle: searching for neighbors
[2025-10-17 16:11:07,018: INFO/MainProcess] mingle: all alone
[2025-10-17 16:11:07,033: INFO/MainProcess] celery@Xaviers-MacBook-Pro.local ready.
[2025-10-17 16:15:24,638: INFO/MainProcess] Connected to redis://localhost:6379/0
[2025-10-17 16:15:24,684: INFO/MainProcess] mingle: searching for neighbors
[2025-10-17 16:15:25,811: INFO/MainProcess] mingle: all alone
[2025-10-17 16:15:25,835: INFO/MainProcess] celery@Xaviers-MacBook-Pro.local ready.
[2025-10-17 16:30:01,090: ERROR/MainProcess] Received unregistered task of type 'backend.bot.tasks.collect_transactions'.
The message has been ignored and discarded.

Did you remember to import the module containing this task?
Or maybe you're using relative imports?

Please see
https://docs.celeryq.dev/en/latest/internals/protocol.html
for more information.

The full contents of the message body was:
b'[[], {}, {"callbacks": null, "errbacks": null, "chain": null, "chord": null}]' (77b)

The full contents of the message headers:
{'lang': 'py', 'task': 'backend.bot.tasks.collect_transactions', 'id': 'f14a4ceb-2058-4a53-af4e-29f21e724a88', 'shadow': None, 'eta': None, 'expires': '2025-10-17T16:55:00.424786-04:00', 'group': None, 'group_index': None, 'retries': 0, 'timelimit': [None, None], 'root_id': 'f14a4ceb-2058-4a53-af4e-29f21e724a88', 'parent_id': None, 'argsrepr': '()', 'kwargsrepr': '{}', 'origin': 'gen26226@Xaviers-MacBook-Pro.local', 'ignore_result': False, 'replaced_task_nesting': 0, 'stamped_headers': None, 'stamps': {}}

The delivery info for this task is:
{'exchange': '', 'routing_key': 'heartbeat_bot'}
Traceback (most recent call last):
  File "/Library/Frameworks/Python.framework/Versions/3.12/lib/python3.12/site-packages/celery/worker/consumer/consumer.py", line 662, in on_task_received
    strategy = strategies[type_]
               ~~~~~~~~~~^^^^^^^
KeyError: 'backend.bot.tasks.collect_transactions'
[2025-10-17 16:30:01,084: ERROR/MainProcess] Received unregistered task of type 'backend.bot.tasks.collect_transactions'.
The message has been ignored and discarded.

Did you remember to import the module containing this task?
Or maybe you're using relative imports?

Please see
https://docs.celeryq.dev/en/latest/internals/protocol.html
for more information.

The full contents of the message body was:
b'[[], {}, {"callbacks": null, "errbacks": null, "chain": null, "chord": null}]' (77b)

The full contents of the message headers:
{'lang': 'py', 'task': 'backend.bot.tasks.collect_transactions', 'id': 'd0d56a48-0e63-46fc-a393-9d183e7fa222', 'shadow': None, 'eta': None, 'expires': '2025-10-17T16:55:00.422979-04:00', 'group': None, 'group_index': None, 'retries': 0, 'timelimit': [None, None], 'root_id': 'd0d56a48-0e63-46fc-a393-9d183e7fa222', 'parent_id': None, 'argsrepr': '()', 'kwargsrepr': '{}', 'origin': 'gen31479@Xaviers-MacBook-Pro.local', 'ignore_result': False, 'replaced_task_nesting': 0, 'stamped_headers': None, 'stamps': {}}

The delivery info for this task is:
{'exchange': '', 'routing_key': 'heartbeat_bot'}
Traceback (most recent call last):
  File "/Library/Frameworks/Python.framework/Versions/3.12/lib/python3.12/site-packages/celery/worker/consumer/consumer.py", line 662, in on_task_received
    strategy = strategies[type_]
               ~~~~~~~~~~^^^^^^^
KeyError: 'backend.bot.tasks.collect_transactions'
[2025-10-17 17:00:00,029: ERROR/MainProcess] Received unregistered task of type 'backend.bot.tasks.collect_transactions'.
The message has been ignored and discarded.

Did you remember to import the module containing this task?
Or maybe you're using relative imports?

Please see
https://docs.celeryq.dev/en/latest/internals/protocol.html
for more information.

The full contents of the message body was:
b'[[], {}, {"callbacks": null, "errbacks": null, "chain": null, "chord": null}]' (77b)

The full contents of the message headers:
{'lang': 'py', 'task': 'backend.bot.tasks.collect_transactions', 'id': '4845e8a0-10f2-495f-b3c1-33f37e4dbf4b', 'shadow': None, 'eta': None, 'expires': '2025-10-17T17:25:00.011765-04:00', 'group': None, 'group_index': None, 'retries': 0, 'timelimit': [None, None], 'root_id': '4845e8a0-10f2-495f-b3c1-33f37e4dbf4b', 'parent_id': None, 'argsrepr': '()', 'kwargsrepr': '{}', 'origin': 'gen31479@Xaviers-MacBook-Pro.local', 'ignore_result': False, 'replaced_task_nesting': 0, 'stamped_headers': None, 'stamps': {}}

The delivery info for this task is:
{'exchange': '', 'routing_key': 'heartbeat_bot'}
Traceback (most recent call last):
  File "/Library/Frameworks/Python.framework/Versions/3.12/lib/python3.12/site-packages/celery/worker/consumer/consumer.py", line 662, in on_task_received
    strategy = strategies[type_]
               ~~~~~~~~~~^^^^^^^
KeyError: 'backend.bot.tasks.collect_transactions'
[2025-10-17 17:00:00,040: ERROR/MainProcess] Received unregistered task of type 'backend.bot.tasks.collect_transactions'.
The message has been ignored and discarded.

Did you remember to import the module containing this task?
Or maybe you're using relative imports?

Please see
https://docs.celeryq.dev/en/latest/internals/protocol.html
for more information.

The full contents of the message body was:
b'[[], {}, {"callbacks": null, "errbacks": null, "chain": null, "chord": null}]' (77b)

The full contents of the message headers:
{'lang': 'py', 'task': 'backend.bot.tasks.collect_transactions', 'id': 'db583754-97d4-44ea-9d2e-38f728d2ed22', 'shadow': None, 'eta': None, 'expires': '2025-10-17T17:25:00.011142-04:00', 'group': None, 'group_index': None, 'retries': 0, 'timelimit': [None, None], 'root_id': 'db583754-97d4-44ea-9d2e-38f728d2ed22', 'parent_id': None, 'argsrepr': '()', 'kwargsrepr': '{}', 'origin': 'gen26226@Xaviers-MacBook-Pro.local', 'ignore_result': False, 'replaced_task_nesting': 0, 'stamped_headers': None, 'stamps': {}}

The delivery info for this task is:
{'exchange': '', 'routing_key': 'heartbeat_bot'}
Traceback (most recent call last):
  File "/Library/Frameworks/Python.framework/Versions/3.12/lib/python3.12/site-packages/celery/worker/consumer/consumer.py", line 662, in on_task_received
    strategy = strategies[type_]
               ~~~~~~~~~~^^^^^^^
KeyError: 'backend.bot.tasks.collect_transactions'
[2025-10-17 17:30:00,038: ERROR/MainProcess] Received unregistered task of type 'backend.bot.tasks.collect_transactions'.
The message has been ignored and discarded.

Did you remember to import the module containing this task?
Or maybe you're using relative imports?

Please see
https://docs.celeryq.dev/en/latest/internals/protocol.html
for more information.

The full contents of the message body was:
b'[[], {}, {"callbacks": null, "errbacks": null, "chain": null, "chord": null}]' (77b)

The full contents of the message headers:
{'lang': 'py', 'task': 'backend.bot.tasks.collect_transactions', 'id': 'a326ad6d-951e-44c8-a4cd-e385faf54460', 'shadow': None, 'eta': None, 'expires': '2025-10-17T17:55:00.014501-04:00', 'group': None, 'group_index': None, 'retries': 0, 'timelimit': [None, None], 'root_id': 'a326ad6d-951e-44c8-a4cd-e385faf54460', 'parent_id': None, 'argsrepr': '()', 'kwargsrepr': '{}', 'origin': 'gen26226@Xaviers-MacBook-Pro.local', 'ignore_result': False, 'replaced_task_nesting': 0, 'stamped_headers': None, 'stamps': {}}

The delivery info for this task is:
{'exchange': '', 'routing_key': 'heartbeat_bot'}
Traceback (most recent call last):
  File "/Library/Frameworks/Python.framework/Versions/3.12/lib/python3.12/site-packages/celery/worker/consumer/consumer.py", line 662, in on_task_received
    strategy = strategies[type_]
               ~~~~~~~~~~^^^^^^^
KeyError: 'backend.bot.tasks.collect_transactions'
[2025-10-17 17:30:00,051: ERROR/MainProcess] Received unregistered task of type 'backend.bot.tasks.collect_transactions'.
The message has been ignored and discarded.

Did you remember to import the module containing this task?
Or maybe you're using relative imports?

Please see
https://docs.celeryq.dev/en/latest/internals/protocol.html
for more information.

The full contents of the message body was:
b'[[], {}, {"callbacks": null, "errbacks": null, "chain": null, "chord": null}]' (77b)

The full contents of the message headers:
{'lang': 'py', 'task': 'backend.bot.tasks.collect_transactions', 'id': 'a9389944-6358-493c-9ab2-759e06579c0b', 'shadow': None, 'eta': None, 'expires': '2025-10-17T17:55:00.015480-04:00', 'group': None, 'group_index': None, 'retries': 0, 'timelimit': [None, None], 'root_id': 'a9389944-6358-493c-9ab2-759e06579c0b', 'parent_id': None, 'argsrepr': '()', 'kwargsrepr': '{}', 'origin': 'gen31479@Xaviers-MacBook-Pro.local', 'ignore_result': False, 'replaced_task_nesting': 0, 'stamped_headers': None, 'stamps': {}}

The delivery info for this task is:
{'exchange': '', 'routing_key': 'heartbeat_bot'}
Traceback (most recent call last):
  File "/Library/Frameworks/Python.framework/Versions/3.12/lib/python3.12/site-packages/celery/worker/consumer/consumer.py", line 662, in on_task_received
    strategy = strategies[type_]
               ~~~~~~~~~~^^^^^^^
KeyError: 'backend.bot.tasks.collect_transactions'
[2025-10-17 17:38:51,501: INFO/MainProcess] Connected to redis://localhost:6379/0
[2025-10-17 17:38:51,502: INFO/MainProcess] mingle: searching for neighbors
[2025-10-17 17:38:52,509: INFO/MainProcess] mingle: all alone
[2025-10-17 17:38:52,517: INFO/MainProcess] celery@Xaviers-MacBook-Pro.local ready.
[2025-10-17 18:00:29,216: ERROR/MainProcess] Received unregistered task of type 'backend.bot.tasks.collect_injury_reports'.
The message has been ignored and discarded.

Did you remember to import the module containing this task?
Or maybe you're using relative imports?

Please see
https://docs.celeryq.dev/en/latest/internals/protocol.html
for more information.

The full contents of the message body was:
b'[[], {}, {"callbacks": null, "errbacks": null, "chain": null, "chord": null}]' (77b)

The full contents of the message headers:
{'lang': 'py', 'task': 'backend.bot.tasks.collect_injury_reports', 'id': '2c5761d0-63dc-4221-965f-f84f46edcdae', 'shadow': None, 'eta': None, 'expires': '2025-10-17T23:00:29.200580-04:00', 'group': None, 'group_index': None, 'retries': 0, 'timelimit': [None, None], 'root_id': '2c5761d0-63dc-4221-965f-f84f46edcdae', 'parent_id': None, 'argsrepr': '()', 'kwargsrepr': '{}', 'origin': 'gen19961@Xaviers-MacBook-Pro.local', 'ignore_result': False, 'replaced_task_nesting': 0, 'stamped_headers': None, 'stamps': {}}

The delivery info for this task is:
{'exchange': '', 'routing_key': 'heartbeat_bot'}
Traceback (most recent call last):
  File "/Library/Frameworks/Python.framework/Versions/3.12/lib/python3.12/site-packages/celery/worker/consumer/consumer.py", line 662, in on_task_received
    strategy = strategies[type_]
               ~~~~~~~~~~^^^^^^^
KeyError: 'backend.bot.tasks.collect_injury_reports'
[2025-10-17 18:00:29,225: ERROR/MainProcess] Received unregistered task of type 'backend.bot.tasks.aggregate_and_synthesize_news'.
The message has been ignored and discarded.

Did you remember to import the module containing this task?
Or maybe you're using relative imports?

Please see
https://docs.celeryq.dev/en/latest/internals/protocol.html
for more information.

The full contents of the message body was:
b'[[], {}, {"callbacks": null, "errbacks": null, "chain": null, "chord": null}]' (77b)

The full contents of the message headers:
{'lang': 'py', 'task': 'backend.bot.tasks.aggregate_and_synthesize_news', 'id': 'd1a15223-1825-4aec-87ab-b9c44f6bc7df', 'shadow': None, 'eta': None, 'expires': '2025-10-17T23:00:29.215915-04:00', 'group': None, 'group_index': None, 'retries': 0, 'timelimit': [None, None], 'root_id': 'd1a15223-1825-4aec-87ab-b9c44f6bc7df', 'parent_id': None, 'argsrepr': '()', 'kwargsrepr': '{}', 'origin': 'gen19961@Xaviers-MacBook-Pro.local', 'ignore_result': False, 'replaced_task_nesting': 0, 'stamped_headers': None, 'stamps': {}}

The delivery info for this task is:
{'exchange': '', 'routing_key': 'heartbeat_bot'}
Traceback (most recent call last):
  File "/Library/Frameworks/Python.framework/Versions/3.12/lib/python3.12/site-packages/celery/worker/consumer/consumer.py", line 662, in on_task_received
    strategy = strategies[type_]
               ~~~~~~~~~~^^^^^^^
KeyError: 'backend.bot.tasks.aggregate_and_synthesize_news'
[2025-10-17 18:00:29,226: ERROR/MainProcess] Received unregistered task of type 'backend.bot.tasks.collect_transactions'.
The message has been ignored and discarded.

Did you remember to import the module containing this task?
Or maybe you're using relative imports?

Please see
https://docs.celeryq.dev/en/latest/internals/protocol.html
for more information.

The full contents of the message body was:
b'[[], {}, {"callbacks": null, "errbacks": null, "chain": null, "chord": null}]' (77b)

The full contents of the message headers:
{'lang': 'py', 'task': 'backend.bot.tasks.collect_transactions', 'id': '95166ca4-10a9-420c-914e-c85d3cd984bf', 'shadow': None, 'eta': None, 'expires': '2025-10-17T18:25:29.217168-04:00', 'group': None, 'group_index': None, 'retries': 0, 'timelimit': [None, None], 'root_id': '95166ca4-10a9-420c-914e-c85d3cd984bf', 'parent_id': None, 'argsrepr': '()', 'kwargsrepr': '{}', 'origin': 'gen19961@Xaviers-MacBook-Pro.local', 'ignore_result': False, 'replaced_task_nesting': 0, 'stamped_headers': None, 'stamps': {}}

The delivery info for this task is:
{'exchange': '', 'routing_key': 'heartbeat_bot'}
Traceback (most recent call last):
  File "/Library/Frameworks/Python.framework/Versions/3.12/lib/python3.12/site-packages/celery/worker/consumer/consumer.py", line 662, in on_task_received
    strategy = strategies[type_]
               ~~~~~~~~~~^^^^^^^
KeyError: 'backend.bot.tasks.collect_transactions'
[2025-10-17 18:29:42,023: INFO/MainProcess] Connected to redis://localhost:6379/0
[2025-10-17 18:29:42,027: INFO/MainProcess] mingle: searching for neighbors
[2025-10-17 18:29:43,033: INFO/MainProcess] mingle: all alone
[2025-10-17 18:29:43,041: INFO/MainProcess] celery@Xaviers-MacBook-Pro.local ready.
[2025-10-17 18:30:00,035: ERROR/MainProcess] Received unregistered task of type 'backend.bot.tasks.collect_transactions'.
The message has been ignored and discarded.

Did you remember to import the module containing this task?
Or maybe you're using relative imports?

Please see
https://docs.celeryq.dev/en/latest/internals/protocol.html
for more information.

The full contents of the message body was:
b'[[], {}, {"callbacks": null, "errbacks": null, "chain": null, "chord": null}]' (77b)

The full contents of the message headers:
{'lang': 'py', 'task': 'backend.bot.tasks.collect_transactions', 'id': '91d1e308-d0c5-4663-b662-a653f95ae394', 'shadow': None, 'eta': None, 'expires': '2025-10-17T18:55:00.024383-04:00', 'group': None, 'group_index': None, 'retries': 0, 'timelimit': [None, None], 'root_id': '91d1e308-d0c5-4663-b662-a653f95ae394', 'parent_id': None, 'argsrepr': '()', 'kwargsrepr': '{}', 'origin': 'gen69769@Xaviers-MacBook-Pro.local', 'ignore_result': False, 'replaced_task_nesting': 0, 'stamped_headers': None, 'stamps': {}}

The delivery info for this task is:
{'exchange': '', 'routing_key': 'heartbeat_bot'}
Traceback (most recent call last):
  File "/Library/Frameworks/Python.framework/Versions/3.12/lib/python3.12/site-packages/celery/worker/consumer/consumer.py", line 662, in on_task_received
    strategy = strategies[type_]
               ~~~~~~~~~~^^^^^^^
KeyError: 'backend.bot.tasks.collect_transactions'
[2025-10-17 19:29:18,783: ERROR/MainProcess] Received unregistered task of type 'backend.bot.tasks.collect_transactions'.
The message has been ignored and discarded.

Did you remember to import the module containing this task?
Or maybe you're using relative imports?

Please see
https://docs.celeryq.dev/en/latest/internals/protocol.html
for more information.

The full contents of the message body was:
b'[[], {}, {"callbacks": null, "errbacks": null, "chain": null, "chord": null}]' (77b)

The full contents of the message headers:
{'lang': 'py', 'task': 'backend.bot.tasks.collect_transactions', 'id': 'c72676c4-f255-4847-b92f-7cc8165f23af', 'shadow': None, 'eta': None, 'expires': '2025-10-17T19:54:18.770639-04:00', 'group': None, 'group_index': None, 'retries': 0, 'timelimit': [None, None], 'root_id': 'c72676c4-f255-4847-b92f-7cc8165f23af', 'parent_id': None, 'argsrepr': '()', 'kwargsrepr': '{}', 'origin': 'gen69769@Xaviers-MacBook-Pro.local', 'ignore_result': False, 'replaced_task_nesting': 0, 'stamped_headers': None, 'stamps': {}}

The delivery info for this task is:
{'exchange': '', 'routing_key': 'heartbeat_bot'}
Traceback (most recent call last):
  File "/Library/Frameworks/Python.framework/Versions/3.12/lib/python3.12/site-packages/celery/worker/consumer/consumer.py", line 662, in on_task_received
    strategy = strategies[type_]
               ~~~~~~~~~~^^^^^^^
KeyError: 'backend.bot.tasks.collect_transactions'
[2025-10-17 19:30:00,005: ERROR/MainProcess] Received unregistered task of type 'backend.bot.tasks.collect_transactions'.
The message has been ignored and discarded.

Did you remember to import the module containing this task?
Or maybe you're using relative imports?

Please see
https://docs.celeryq.dev/en/latest/internals/protocol.html
for more information.

The full contents of the message body was:
b'[[], {}, {"callbacks": null, "errbacks": null, "chain": null, "chord": null}]' (77b)

The full contents of the message headers:
{'lang': 'py', 'task': 'backend.bot.tasks.collect_transactions', 'id': '0a3de8df-90d0-403a-b31a-74534cd85ee5', 'shadow': None, 'eta': None, 'expires': '2025-10-17T19:55:00.001942-04:00', 'group': None, 'group_index': None, 'retries': 0, 'timelimit': [None, None], 'root_id': '0a3de8df-90d0-403a-b31a-74534cd85ee5', 'parent_id': None, 'argsrepr': '()', 'kwargsrepr': '{}', 'origin': 'gen69769@Xaviers-MacBook-Pro.local', 'ignore_result': False, 'replaced_task_nesting': 0, 'stamped_headers': None, 'stamps': {}}

The delivery info for this task is:
{'exchange': '', 'routing_key': 'heartbeat_bot'}
Traceback (most recent call last):
  File "/Library/Frameworks/Python.framework/Versions/3.12/lib/python3.12/site-packages/celery/worker/consumer/consumer.py", line 662, in on_task_received
    strategy = strategies[type_]
               ~~~~~~~~~~^^^^^^^
KeyError: 'backend.bot.tasks.collect_transactions'
[2025-10-17 20:00:00,008: ERROR/MainProcess] Received unregistered task of type 'backend.bot.tasks.collect_transactions'.
The message has been ignored and discarded.

Did you remember to import the module containing this task?
Or maybe you're using relative imports?

Please see
https://docs.celeryq.dev/en/latest/internals/protocol.html
for more information.

The full contents of the message body was:
b'[[], {}, {"callbacks": null, "errbacks": null, "chain": null, "chord": null}]' (77b)

The full contents of the message headers:
{'lang': 'py', 'task': 'backend.bot.tasks.collect_transactions', 'id': '83bf8651-1875-46c3-b5b5-8f9e9c39e952', 'shadow': None, 'eta': None, 'expires': '2025-10-17T20:25:00.002136-04:00', 'group': None, 'group_index': None, 'retries': 0, 'timelimit': [None, None], 'root_id': '83bf8651-1875-46c3-b5b5-8f9e9c39e952', 'parent_id': None, 'argsrepr': '()', 'kwargsrepr': '{}', 'origin': 'gen69769@Xaviers-MacBook-Pro.local', 'ignore_result': False, 'replaced_task_nesting': 0, 'stamped_headers': None, 'stamps': {}}

The delivery info for this task is:
{'exchange': '', 'routing_key': 'heartbeat_bot'}
Traceback (most recent call last):
  File "/Library/Frameworks/Python.framework/Versions/3.12/lib/python3.12/site-packages/celery/worker/consumer/consumer.py", line 662, in on_task_received
    strategy = strategies[type_]
               ~~~~~~~~~~^^^^^^^
KeyError: 'backend.bot.tasks.collect_transactions'
[2025-10-17 20:30:00,006: ERROR/MainProcess] Received unregistered task of type 'backend.bot.tasks.collect_transactions'.
The message has been ignored and discarded.

Did you remember to import the module containing this task?
Or maybe you're using relative imports?

Please see
https://docs.celeryq.dev/en/latest/internals/protocol.html
for more information.

The full contents of the message body was:
b'[[], {}, {"callbacks": null, "errbacks": null, "chain": null, "chord": null}]' (77b)

The full contents of the message headers:
{'lang': 'py', 'task': 'backend.bot.tasks.collect_transactions', 'id': '44f98d25-e7b3-42ab-8693-62a92bdd17ee', 'shadow': None, 'eta': None, 'expires': '2025-10-17T20:55:00.001968-04:00', 'group': None, 'group_index': None, 'retries': 0, 'timelimit': [None, None], 'root_id': '44f98d25-e7b3-42ab-8693-62a92bdd17ee', 'parent_id': None, 'argsrepr': '()', 'kwargsrepr': '{}', 'origin': 'gen69769@Xaviers-MacBook-Pro.local', 'ignore_result': False, 'replaced_task_nesting': 0, 'stamped_headers': None, 'stamps': {}}

The delivery info for this task is:
{'exchange': '', 'routing_key': 'heartbeat_bot'}
Traceback (most recent call last):
  File "/Library/Frameworks/Python.framework/Versions/3.12/lib/python3.12/site-packages/celery/worker/consumer/consumer.py", line 662, in on_task_received
    strategy = strategies[type_]
               ~~~~~~~~~~^^^^^^^
KeyError: 'backend.bot.tasks.collect_transactions'
[2025-10-17 21:00:00,010: ERROR/MainProcess] Received unregistered task of type 'backend.bot.tasks.collect_transactions'.
The message has been ignored and discarded.

Did you remember to import the module containing this task?
Or maybe you're using relative imports?

Please see
https://docs.celeryq.dev/en/latest/internals/protocol.html
for more information.

The full contents of the message body was:
b'[[], {}, {"callbacks": null, "errbacks": null, "chain": null, "chord": null}]' (77b)

The full contents of the message headers:
{'lang': 'py', 'task': 'backend.bot.tasks.collect_transactions', 'id': '96c89641-5877-4aac-90bf-17b18d5e8de7', 'shadow': None, 'eta': None, 'expires': '2025-10-17T21:25:00.006016-04:00', 'group': None, 'group_index': None, 'retries': 0, 'timelimit': [None, None], 'root_id': '96c89641-5877-4aac-90bf-17b18d5e8de7', 'parent_id': None, 'argsrepr': '()', 'kwargsrepr': '{}', 'origin': 'gen69769@Xaviers-MacBook-Pro.local', 'ignore_result': False, 'replaced_task_nesting': 0, 'stamped_headers': None, 'stamps': {}}

The delivery info for this task is:
{'exchange': '', 'routing_key': 'heartbeat_bot'}
Traceback (most recent call last):
  File "/Library/Frameworks/Python.framework/Versions/3.12/lib/python3.12/site-packages/celery/worker/consumer/consumer.py", line 662, in on_task_received
    strategy = strategies[type_]
               ~~~~~~~~~~^^^^^^^
KeyError: 'backend.bot.tasks.collect_transactions'
[2025-10-17 21:30:00,097: ERROR/MainProcess] Received unregistered task of type 'backend.bot.tasks.collect_transactions'.
The message has been ignored and discarded.

Did you remember to import the module containing this task?
Or maybe you're using relative imports?

Please see
https://docs.celeryq.dev/en/latest/internals/protocol.html
for more information.

The full contents of the message body was:
b'[[], {}, {"callbacks": null, "errbacks": null, "chain": null, "chord": null}]' (77b)

The full contents of the message headers:
{'lang': 'py', 'task': 'backend.bot.tasks.collect_transactions', 'id': 'b7f06366-9d5e-45aa-a5b0-97a2fa7166ae', 'shadow': None, 'eta': None, 'expires': '2025-10-17T21:55:00.011792-04:00', 'group': None, 'group_index': None, 'retries': 0, 'timelimit': [None, None], 'root_id': 'b7f06366-9d5e-45aa-a5b0-97a2fa7166ae', 'parent_id': None, 'argsrepr': '()', 'kwargsrepr': '{}', 'origin': 'gen69769@Xaviers-MacBook-Pro.local', 'ignore_result': False, 'replaced_task_nesting': 0, 'stamped_headers': None, 'stamps': {}}

The delivery info for this task is:
{'exchange': '', 'routing_key': 'heartbeat_bot'}
Traceback (most recent call last):
  File "/Library/Frameworks/Python.framework/Versions/3.12/lib/python3.12/site-packages/celery/worker/consumer/consumer.py", line 662, in on_task_received
    strategy = strategies[type_]
               ~~~~~~~~~~^^^^^^^
KeyError: 'backend.bot.tasks.collect_transactions'
[2025-10-17 21:34:30,019: INFO/MainProcess] Connected to redis://localhost:6379/0
[2025-10-17 21:34:30,021: INFO/MainProcess] mingle: searching for neighbors
[2025-10-17 21:34:31,025: INFO/MainProcess] mingle: all alone
[2025-10-17 21:34:31,034: INFO/MainProcess] celery@Mac ready.
[2025-10-17 21:35:54,185: INFO/MainProcess] Connected to redis://localhost:6379/0
[2025-10-17 21:35:54,187: INFO/MainProcess] mingle: searching for neighbors
[2025-10-17 21:35:55,192: INFO/MainProcess] mingle: all alone
[2025-10-17 21:35:55,200: INFO/MainProcess] celery@Mac ready.
[2025-10-17 21:40:12,178: INFO/MainProcess] Connected to redis://localhost:6379/0
[2025-10-17 21:40:12,180: INFO/MainProcess] mingle: searching for neighbors
[2025-10-17 21:40:13,187: INFO/MainProcess] mingle: all alone
[2025-10-17 21:40:13,197: INFO/MainProcess] celery@Mac ready.
